Workbook

Sheet Assumptions
A1: (Unless otherwise specified, all financials are in USD Mn) | E1: Historical | H1: Forecasted
D2: Units | E2: =PnL!E2 -> 2016 | F2: =PnL!F2 -> 2017 | G2: =PnL!G2 -> 2018 | H2: =PnL!H2 -> 2019 | I2: =PnL!I2 -> 2020 | J2: =PnL!J2 -> 2021 | K2: =PnL!K2 -> 2022 | L2: =PnL!L2 -> 2023
A4: Balance Sheet Assumptions
B5: Key Ratios
C6: Inventory (Days of raw materials cost) | D6: # days | E6: =365/(PnL!E7/BS!E31) -> 94.132727 | F6: =365/(PnL!F7/BS!F31) -> 77.710215 | G6: =365/(PnL!G7/BS!G31) -> 71.998602 | H6: =AVERAGE(F6:G6) -> 74.854408 | I6: =H6 -> 74.854408 | J6: =I6 -> 74.854408 | K6: =J6 -> 74.854408 | L6: =K6 -> 74.854408
C7: Accounts Receivables (days of sales) | D7: # days | E7: =365/(PnL!E7/BS!E30) -> 124.97012 | F7: =365/(PnL!F7/BS!F30) -> 85.1211 | G7: =365/(PnL!G7/BS!G30) -> 92.569632 | H7: =AVERAGE(F7:G7) -> 88.845366 | I7: =H7 -> 88.845366 | J7: =I7 -> 88.845366 | K7: =J7 -> 88.845366 | L7: =K7 -> 88.845366
C8: Accounts Payables (days of raw material costs) | D8: # days | E8: =365/(PnL!E10/BS!E9) -> 189.66309 | F8: =365/(PnL!F10/BS!F9) -> 153.89821 | G8: =365/(PnL!G10/BS!G9) -> 129.93528 | H8: =AVERAGE(F8:G8) -> 141.91674 | I8: =H8 -> 141.91674 | J8: =I8 -> 141.91674 | K8: =J8 -> 141.91674 | L8: =K8 -> 141.91674
C9: Accrued Liability (days of raw material costs) | D9: # days | E9: =365/(PnL!E10/BS!E10) -> 171.87887 | F9: =365/(PnL!F10/BS!F10) -> 105.16743 | G9: =365/(PnL!G10/BS!G10) -> 98.189725 | H9: =AVERAGE(F9:G9) -> 101.67858 | I9: =H9 -> 101.67858 | J9: =I9 -> 101.67858 | K9: =J9 -> 101.67858 | L9: =K9 -> 101.67858
C10: Deferred Revenue (days of sales) | D10: # days | E10: =365/(PnL!E7/BS!E11) -> 41.667094 | F10: =365/(PnL!F7/BS!F11) -> 60.910819 | G10: =365/(PnL!G7/BS!G11) -> 47.313367 | H10: =AVERAGE(F10:G10) -> 54.112093 | I10: =H10 -> 54.112093 | J10: =I10 -> 54.112093 | K10: =J10 -> 54.112093 | L10: =K10 -> 54.112093
B12: Prepaid Expenses and other current assets | D12: Mn $ | F12: =BS!E32 -> 21.72 | G12: =BS!F32 -> 21.97 | H12: =G12 -> 21.97 | I12: =H12 -> 21.97 | J12: =I12 -> 21.97 | K12: =J12 -> 21.97 | L12: =K12 -> 21.97
A15: Revenue Assumptions
B16: Sales Prices
C17: Cameras | D17: USD/ Item | E17: 400 | F17: 419.99979 | G17: 439.99995 | H17: =G17*(1+H18) -> 461.47611 | I17: =H17*(1+I18) -> 483.72594 | J17: =I17*(1+J18) -> 507.19243 | K17: =J17*(1+K18) -> 531.72189 | L17: =K17*(1+L18) -> 557.47721 | N17: ctrl+r
C18: Inflation % | F18: =(F17/E17)-1 -> 0.049999468 | G18: =(G17/F17)-1 -> 0.047619462 | H18: =AVERAGE(F18:G18) -> 0.048809465 | I18: =AVERAGE(G18:H18) -> 0.048214464 | J18: =AVERAGE(H18:I18) -> 0.048511964 | K18: =AVERAGE(I18:J18) -> 0.048363214 | L18: =AVERAGE(J18:K18) -> 0.048437589
C19: Accessories | D19: USD/ Item | E19: 25 | F19: 27.999997 | G19: 35 | H19: =G19*(1+H20) -> 41.475 | I19: =H19*(1+I20) -> 49.147875 | J19: =I19*(1+J20) -> 58.240233 | K19: =J19*(1+K20) -> 69.014676 | L19: =K19*(1+L20) -> 81.782392
C20: Inflation % | F20: =(F19/E19)-1 -> 0.1199999 | G20: =(G19/F19)-1 -> 0.25000011 | H20: =AVERAGE(F20:G20) -> 0.18500001 | I20: =H20 -> 0.18500001 | J20: =I20 -> 0.18500001 | K20: =J20 -> 0.18500001 | L20: =K20 -> 0.18500001
B22: Sales Volumes
C23: Cameras | D23: Items | E23: 468475 | F23: 939310 | G23: 1635432 | H23: =G23*(1+H24) -> 1308345.6 | I23: =H23*(1+I24) -> 1177511 | J23: =I23*(1+J24) -> 1177511 | K23: =J23*(1+K24) -> 1295262.1 | L23: =K23*(1+L24) -> 1424788.4
C24: Growth % | F24: =(F23/E23)-1 -> 1.0050376 | G24: =(G23/F23)-1 -> 0.74109932 | H24: -0.2 | I24: -0.1 | J24: 0 | K24: 0.1 | L24: 0.1
C25: Accessories | D25: Items | E25: 1874000 | F25: 4696429 | G25: 4788000 | H25: =G25*(1+H26) -> 2394000 | I25: =H25*(1+I26) -> 1795500 | J25: =I25*(1+J26) -> 1795500 | K25: =J25*(1+K26) -> 1975050 | L25: =K25*(1+L26) -> 2172555
C26: Growth % | F26: =(F25/E25)-1 -> 1.5060987 | G26: =(G25/F25)-1 -> 0.019498006 | H26: -0.5 | I26: -0.25 | J26: 0 | K26: 0.1 | L26: 0.1
A28: Cost Assumptions
B29: Raw Material
C30: Cameras | D30: USD/ Item | E30: 198.72 | F30: 264.94 | G30: 287.19 | H30: =G30*(1+H31) -> 311.30858 | I30: =H30*(1+I31) -> 337.45268 | J30: =I30*(1+J31) -> 365.79238 | K30: =J30*(1+K31) -> 396.5121 | L30: =K30*(1+L31) -> 429.81169
C31: Inflation % | F31: =F30/E30-1 -> 0.33323269 | G31: =G30/F30-1 -> 0.083981279 | H31: =G31 -> 0.083981279 | I31: =H31 -> 0.083981279 | J31: =I31 -> 0.083981279 | K31: =J31 -> 0.083981279 | L31: =K31 -> 0.083981279
C32: Accessories | D32: USD/ Item | E32: 5.52 | F32: 10.85 | G32: 5.16 | H32: =G32*(1+H33) -> 5.5933434 | I32: =H32*(1+I33) -> 6.0630795 | J32: =I32*(1+J33) -> 6.5722647 | K32: =J32*(1+K33) -> 7.1242119 | L32: =K32*(1+L33) -> 7.7225123
C33: Inflation % | F33: =F32/E32-1 -> 0.96557971 | G33: =G32/F32-1 -> -0.52442396 | H33: =H31 -> 0.083981279 | I33: =I31 -> 0.083981279 | J33: =J31 -> 0.083981279 | K33: =K31 -> 0.083981279 | L33: =L31 -> 0.083981279
B35: Research and Development | D35: USD | E35: 18740000 | F35: 31560000 | G35: 87830000 | H35: =PnL!H7*Assumptions!H36 -> 56.011136 | I35: =PnL!I7*Assumptions!I36 -> 45.829896 | J35: =PnL!J7*Assumptions!J36 -> 41.874347 | K35: =PnL!K7*Assumptions!K36 -> 40.977003 | L35: =PnL!L7*Assumptions!L36 -> 48.275001
C36: %age of sales | E36: =E35/10^6/PnL!E$7 -> 0.080003415 | F36: =F35/10^6/PnL!F$7 -> 0.059998859 | G36: =G35/10^6/PnL!G$7 -> 0.099000192 | H36: =AVERAGE(E36:G36) -> 0.079667489 | I36: =H36-1% -> 0.069667489 | J36: =I36-1% -> 0.059667489 | K36: =J36-1% -> 0.049667489 | L36: =K36 -> 0.049667489
B37: Sales and Marketing | D37: USD | E37: 57700000 | F37: 120980000 | G37: 150820000 | H37: =PnL!H7*Assumptions!H38 -> 119.52131 | I37: =PnL!I7*Assumptions!I38 -> 118.41159 | J37: =PnL!J7*Assumptions!J38 -> 133.34193 | K37: =PnL!K7*Assumptions!K38 -> 165.00636 | L37: =PnL!L7*Assumptions!L38 -> 204.1136
C38: %age of sales | E38: =E37/10^6/PnL!E$7 -> 0.24632855 | F38: =F37/10^6/PnL!F$7 -> 0.22999563 | G38: =G37/10^6/PnL!G$7 -> 0.17000124 | H38: =G38 -> 0.17000124 | I38: =H38+1% -> 0.18000124 | J38: =I38+1% -> 0.19000124 | K38: =J38+1% -> 0.20000124 | L38: =K38+1% -> 0.21000124
B39: G&A | D39: USD | E39: 8200000 | F39: 17360000 | G39: 26620000 | H39: =PnL!H7*Assumptions!H40 -> 22.970311 | I39: =PnL!I7*Assumptions!I40 -> 20.980754 | J39: =PnL!J7*Assumptions!J40 -> 22.123124 | K39: =PnL!K7*Assumptions!K40 -> 26.425325 | L39: =PnL!L7*Assumptions!L40 -> 30.923612
C40: %age of sales | E40: =E39/10^6/PnL!E$7 -> 0.035006831 | F40: =F39/10^6/PnL!F$7 -> 0.033003175 | G40: =G39/10^6/PnL!G$7 -> 0.030005523 | H40: =AVERAGE(E40:G40) -> 0.032671843 | I40: =AVERAGE(F40:H40) -> 0.031893514 | J40: =AVERAGE(G40:I40) -> 0.031523627 | K40: =AVERAGE(H40:J40) -> 0.032029661 | L40: =AVERAGE(I40:K40) -> 0.0318156
A42: Asset Schedule Assumptions
B43: Capex | D43: USD | E43: 200000000 | F43: 0 | G43: 200000000 | H43: 0 | I43: 0 | J43: 0 | K43: 0 | L43: 0
B44: Asset Life (SLM Method) | D44: Years | E44: 10 | F44: =E44 -> 10 | G44: =F44 -> 10 | H44: =G44 -> 10 | I44: =H44 -> 10 | J44: =I44 -> 10 | K44: =J44 -> 10 | L44: =K44 -> 10 | N44: Test with 5 years and then replace back to Original Value 10 yrs
B45: Disposal of Assets | D45: USD | E45: 0 | F45: 0 | G45: 0 | H45: 0 | I45: 0 | J45: 0 | K45: 0 | L45: 0
A47: Financing Assumptions
B48: Interest Rates
C49: Interest rate on Secured Loans | D49: % | H49: 0.1 | I49: 0.1 | J49: 0.1 | K49: 0.1 | L49: 0.1
...

Sheet PnL
A1: (Unless otherwise specified, all financials are in USD Mn) | E1: Historical | H1: Forecasted
E2: 2016 | F2: =E2+1 -> 2017 | G2: =F2+1 -> 2018 | H2: =G2+1 -> 2019 | I2: =H2+1 -> 2020 | J2: =I2+1 -> 2021 | K2: =J2+1 -> 2022 | L2: =K2+1 -> 2023
A4: Revenues
B5: Cameras | E5: 187.39 | F5: 394.51 | G5: 719.59 | H5: =(Assumptions!H17*Assumptions!H23)/10^6 -> 603.77024 | I5: =(Assumptions!I17*Assumptions!I23)/10^6 -> 569.59263 | J5: =(Assumptions!J17*Assumptions!J23)/10^6 -> 597.22469 | K5: =(Assumptions!K17*Assumptions!K23)/10^6 -> 688.71923 | L5: =(Assumptions!L17*Assumptions!L23)/10^6 -> 794.28705 | N5: Assumptions
B6: Accessories | E6: 46.85 | F6: 131.5 | G6: 167.58 | H6: =(Assumptions!H19*Assumptions!H25)/10^6 -> 99.29115 | I6: =(Assumptions!I19*Assumptions!I25)/10^6 -> 88.24501 | J6: =(Assumptions!J19*Assumptions!J25)/10^6 -> 104.57034 | K6: =(Assumptions!K19*Assumptions!K25)/10^6 -> 136.30744 | L6: =(Assumptions!L19*Assumptions!L25)/10^6 -> 177.67674 | N6: Assumptions
B7: Total | E7: =SUM(E5:E6) -> 234.24 | F7: =SUM(F5:F6) -> 526.01 | G7: =SUM(G5:G6) -> 887.17 | H7: =SUM(H5:H6) -> 703.06139 | I7: =SUM(I5:I6) -> 657.83764 | J7: =SUM(J5:J6) -> 701.79503 | K7: =SUM(K5:K6) -> 825.02667 | L7: =SUM(L5:L6) -> 971.96379
A9: Operating Costs
B10: Raw Material Cost | E10: 103.44 | F10: 299.83 | G10: 494.4 | H10: =Assumptions!H30 -> 311.30858 | I10: =Assumptions!I30 -> 337.45268 | J10: =Assumptions!J30 -> 365.79238 | K10: =Assumptions!K30 -> 396.5121 | L10: =Assumptions!L30 -> 429.81169 | N10: Assumptions
B11: Research and Development | E11: 18.74 | F11: 31.56 | G11: 87.83 | H11: =Assumptions!H35 -> 56.011136 | I11: =Assumptions!I35 -> 45.829896 | J11: =Assumptions!J35 -> 41.874347 | K11: =Assumptions!K35 -> 40.977003 | L11: =Assumptions!L35 -> 48.275001 | N11: Assumptions
B12: Sales and Marketing | E12: 57.7 | F12: 120.98 | G12: 150.82 | H12: =Assumptions!H37 -> 119.52131 | I12: =Assumptions!I37 -> 118.41159 | J12: =Assumptions!J37 -> 133.34193 | K12: =Assumptions!K37 -> 165.00636 | L12: =Assumptions!L37 -> 204.1136 | N12: Assumptions
B13: General and Adminstration | E13: 8.2 | F13: 17.36 | G13: 26.62 | H13: =Assumptions!H39 -> 22.970311 | I13: =Assumptions!I39 -> 20.980754 | J13: =Assumptions!J39 -> 22.123124 | K13: =Assumptions!K39 -> 26.425325 | L13: =Assumptions!L39 -> 30.923612 | N13: Assumptions
B14: Total Operating Costs | E14: =SUM(E10:E13) -> 188.08 | F14: =SUM(F10:F13) -> 469.73 | G14: =SUM(G10:G13) -> 759.67 | H14: =SUM(H10:H13) -> 509.81134 | I14: =SUM(I10:I13) -> 522.67492 | J14: =SUM(J10:J13) -> 563.13178 | K14: =SUM(K10:K13) -> 628.92078 | L14: =SUM(L10:L13) -> 713.1239
A16: EBITDA | E16: =E7-E14 -> 46.16 | F16: =F7-F14 -> 56.28 | G16: =G7-G14 -> 127.5 | H16: =H7-H14 -> 193.25005 | I16: =I7-I14 -> 135.16272 | J16: =J7-J14 -> 138.66325 | K16: =K7-K14 -> 196.10589 | L16: =L7-L14 -> 258.83989
B17: Depreciation | E17: 20 | F17: 20 | G17: 40 | H17: ='Asset Schedule'!H20 -> 40 | I17: ='Asset Schedule'!I20 -> 40 | J17: ='Asset Schedule'!J20 -> 40 | K17: ='Asset Schedule'!K20 -> 40 | L17: ='Asset Schedule'!L20 -> 40 | N17: Asset Schedule
A18: EBIT | E18: =E16-E17 -> 26.16 | F18: =F16-F17 -> 36.28 | G18: =G16-G17 -> 87.5 | H18: =H16-H17 -> 153.25005 | I18: =I16-I17 -> 95.162723 | J18: =J16-J17 -> 98.663246 | K18: =K16-K17 -> 156.10589 | L18: =L16-L17 -> 218.83989
B19: Interest expense | E19: 20 | F19: 19.5 | G19: 28.5 | H19: ='Debt Schedule'!H34 -> 16.721433 | I19: ='Debt Schedule'!I34 -> 8.9156566 | J19: ='Debt Schedule'!J34 -> 1.0821347 | K19: ='Debt Schedule'!K34 -> -9.2096266 | L19: ='Debt Schedule'!L34 -> -22.636351 | N19: Debt Schedule
A20: PBT | E20: =E18-E19 -> 6.16 | F20: =F18-F19 -> 16.78 | G20: =G18-G19 -> 59 | H20: =H18-H19 -> 136.52862 | I20: =I18-I19 -> 86.247067 | J20: =J18-J19 -> 97.581111 | K20: =K18-K19 -> 165.31552 | L20: =L18-L19 -> 241.47624
B21: Taxes | E21: 1.85 | F21: 5.03 | G21: 17.7 | H21: =H20*Assumptions!H68 -> 40.958586 | I21: =I20*Assumptions!I68 -> 25.87412 | J21: =J20*Assumptions!J68 -> 29.274333 | K21: =K20*Assumptions!K68 -> 49.594655 | L21: =L20*Assumptions!L68 -> 72.442872 | N21: Assumptions
A22: PAT | E22: =E20-E21 -> 4.31 | F22: =F20-F21 -> 11.75 | G22: =G20-G21 -> 41.3 | H22: =H20-H21 -> 95.570035 | I22: =I20-I21 -> 60.372947 | J22: =J20-J21 -> 68.306778 | K22: =K20-K21 -> 115.72086 | L22: =L20-L21 -> 169.03337

Sheet BS
A1: (Unless otherwise specified, all financials are in USD Mn) | E1: Historical | H1: Forecasted
E2: =PnL!E2 -> 2016 | F2: =PnL!F2 -> 2017 | G2: =PnL!G2 -> 2018 | H2: =PnL!H2 -> 2019 | I2: =PnL!I2 -> 2020 | J2: =PnL!J2 -> 2021 | K2: =PnL!K2 -> 2022 | L2: =PnL!L2 -> 2023
A3: Sources of Funds
A5: Liabilities
A7: Current Liabilities & Provisions
B8: Overdraft | E8: 0 | F8: 0 | G8: 0 | H8: 0 | I8: 0 | J8: 0 | K8: 0 | L8: 0 | N8: CF
B9: Accounts payable | E9: 53.75 | F9: 126.42 | G9: 176 | H9: =PnL!H10*Assumptions!H8/365 -> 121.04082 | I9: =PnL!I10*Assumptions!I8/365 -> 131.20598 | J9: =PnL!J10*Assumptions!J8/365 -> 142.22483 | K9: =PnL!K10*Assumptions!K8/365 -> 154.16905 | L9: =PnL!L10*Assumptions!L8/365 -> 167.11637 | N9: Assumptions, P&L
B10: Accrued liabilities | E10: 48.71 | F10: 86.39 | G10: 133 | H10: =(PnL!H10*Assumptions!H9)/365 -> 86.721681 | I10: =(PnL!I10*Assumptions!I9)/365 -> 94.004679 | J10: =(PnL!J10*Assumptions!J9)/365 -> 101.89931 | K10: =(PnL!K10*Assumptions!K9)/365 -> 110.45695 | L10: =(PnL!L10*Assumptions!L9)/365 -> 119.73326 | N10: Assumptions, P&L
B11: Deferred revenue | E11: 26.74 | F11: 87.78 | G11: 115 | H11: =PnL!H7*Assumptions!H10/365 -> 104.23048 | I11: =PnL!I7*Assumptions!I10/365 -> 97.52595 | J11: =PnL!J7*Assumptions!J10/365 -> 104.04273 | K11: =PnL!K7*Assumptions!K10/365 -> 122.31211 | L11: =PnL!L7*Assumptions!L10/365 -> 144.09588 | N11: Assumptions, P&L
B12: Total Current Liabilities & Provisions | E12: =SUM(E8:E11) -> 129.2 | F12: =SUM(F8:F11) -> 300.59 | G12: =SUM(G8:G11) -> 424 | H12: =SUM(H8:H11) -> 311.99298 | I12: =SUM(I8:I11) -> 322.73661 | J12: =SUM(J8:J11) -> 348.16688 | K12: =SUM(K8:K11) -> 386.93811 | L12: =SUM(L8:L11) -> 430.94551
A14: Non Current Liabilities
B15: Secured Loans | E15: 0 | F15: 0 | G15: 0 | H15: ='Debt Schedule'!H18 -> 0 | I15: ='Debt Schedule'!I18 -> 0 | J15: ='Debt Schedule'!J18 -> 0 | K15: ='Debt Schedule'!K18 -> 0 | L15: ='Debt Schedule'!L18 -> 0 | N15: Debt Schedule
B16: Unsecured Loans | E16: 200 | F16: 190 | G16: 380 | H16: ='Debt Schedule'!H8 -> 360 | I16: ='Debt Schedule'!I8 -> 340 | J16: ='Debt Schedule'!J8 -> 320 | K16: ='Debt Schedule'!K8 -> 300 | L16: ='Debt Schedule'!L8 -> 280 | N16: Debt Schedule
B17: Total Non Current Liabilities | E17: =SUM(E15:E16) -> 200 | F17: =SUM(F15:F16) -> 190 | G17: =SUM(G15:G16) -> 380 | H17: =SUM(H15:H16) -> 360 | I17: =SUM(I15:I16) -> 340 | J17: =SUM(J15:J16) -> 320 | K17: =SUM(K15:K16) -> 300 | L17: =SUM(L15:L16) -> 280
A19: Shareholders Equity
B20: Paid-up Capital | E20: 50 | F20: 50 | G20: 50 | H20: ='Equity Sch_Other'!H7 -> 50 | I20: ='Equity Sch_Other'!I7 -> 50 | J20: ='Equity Sch_Other'!J7 -> 50 | K20: ='Equity Sch_Other'!K7 -> 50 | L20: ='Equity Sch_Other'!L7 -> 50 | N20: Equity Schedule
B21: Retained Earnings | E21: 4.31 | F21: 16.06 | G21: 57.36 | H21: ='Equity Sch_Other'!H13 -> 152.93003 | I21: ='Equity Sch_Other'!I13 -> 213.30298 | J21: ='Equity Sch_Other'!J13 -> 281.60976 | K21: ='Equity Sch_Other'!K13 -> 397.33062 | L21: ='Equity Sch_Other'!L13 -> 566.36399 | N21: Equity Schedule
B22: Total Shareholders' Equity | E22: =E20+E21 -> 54.31 | F22: =F20+F21 -> 66.06 | G22: =G20+G21 -> 107.36 | H22: =H20+H21 -> 202.93003 | I22: =I20+I21 -> 263.30298 | J22: =J20+J21 -> 331.60976 | K22: =K20+K21 -> 447.33062 | L22: =L20+L21 -> 616.36399
A24: Total Liabilities & Shareholders' Equity | E24: =E12+E17+E22 -> 383.51 | F24: =F12+F17+F22 -> 556.65 | G24: =G12+G17+G22 -> 911.36 | H24: =H12+H17+H22 -> 874.92301 | I24: =I12+I17+I22 -> 926.0396 | J24: =J12+J17+J22 -> 999.77664 | K24: =K12+K17+K22 -> 1134.2687 | L24: =L12+L17+L22 -> 1327.3095
A26: Usage of Funds
A28: Current Assets
B29: Cash | E29: 41.18 | F29: 140.02 | G29: 169.36 | H29: =CF!H41 -> 337.97612 | I29: =CF!I41 -> 434.73906 | J29: =CF!J41 -> 531.96442 | K29: =CF!K41 -> 670.16044 | L29: =CF!L41 -> 860.60586 | N29: CF
B30: Accounts receivable | E30: 80.2 | F30: 122.67 | G30: 225 | H30: =PnL!H7*Assumptions!H7/365 -> 171.13355 | I30: =PnL!I7*Assumptions!I7/365 -> 160.12555 | J30: =PnL!J7*Assumptions!J7/365 -> 170.8253 | K30: =PnL!K7*Assumptions!K7/365 -> 200.82136 | L30: =PnL!L7*Assumptions!L7/365 -> 236.58761 | N30: Assumptions, P&L
B31: Inventories,net | E31: 60.41 | F31: 111.99 | G31: 175 | H31: =PnL!H10*Assumptions!H6/365 -> 63.843342 | I31: =PnL!I10*Assumptions!I6/365 -> 69.204988 | J31: =PnL!J10*Assumptions!J6/365 -> 75.016911 | K31: =PnL!K10*Assumptions!K6/365 -> 81.316927 | L31: =PnL!L10*Assumptions!L6/365 -> 88.146027 | N31: Assumptions, P&L
B32: Prepaid Expenses and other current assets | E32: 21.72 | F32: 21.97 | G32: 22 | H32: =Assumptions!H12 -> 21.97 | I32: =Assumptions!I12 -> 21.97 | J32: =Assumptions!J12 -> 21.97 | K32: =Assumptions!K12 -> 21.97 | L32: =Assumptions!L12 -> 21.97 | N32: Assumptions or from here
B33: Total Current Assets | E33: =SUM(E29:E32) -> 203.51 | F33: =SUM(F29:F32) -> 396.65 | G33: =SUM(G29:G32) -> 591.36 | H33: =SUM(H29:H32) -> 594.92301 | I33: =SUM(I29:I32) -> 686.0396 | J33: =SUM(J29:J32) -> 799.77664 | K33: =SUM(K29:K32) -> 974.26873 | L33: =SUM(L29:L32) -> 1207.3095
A35: Non Current Assets
B36: Gross Block | E36: 200 | F36: 200 | G36: 400 | H36: ='Asset Schedule'!H26 -> 400 | I36: ='Asset Schedule'!I26 -> 400 | J36: ='Asset Schedule'!J26 -> 400 | K36: ='Asset Schedule'!K26 -> 400 | L36: ='Asset Schedule'!L26 -> 400 | N36: Asset Schedule
B37: Accumulated depreciation | E37: 20 | F37: 40 | G37: 80 | H37: ='Asset Schedule'!H31 -> 120 | I37: ='Asset Schedule'!I31 -> 160 | J37: ='Asset Schedule'!J31 -> 200 | K37: ='Asset Schedule'!K31 -> 240 | L37: ='Asset Schedule'!L31 -> 280 | N37: Asset Schedule
B38: Net Block | E38: =E36-E37 -> 180 | F38: =F36-F37 -> 160 | G38: =G36-G37 -> 320 | H38: =H36-H37 -> 280 | I38: =I36-I37 -> 240 | J38: =J36-J37 -> 200 | K38: =K36-K37 -> 160 | L38: =L36-L37 -> 120
B39: WIP | E39: 0 | F39: 0 | G39: 0 | N39: Ignore this (Seems got left by mistake in template)
A41: Total Assets | E41: =E33+E38 -> 383.51 | F41: =F33+F38 -> 556.65 | G41: =G33+G38 -> 911.36 | H41: =H33+H38 -> 874.92301 | I41: =I33+I38 -> 926.0396 | J41: =J33+J38 -> 999.77664 | K41: =K33+K38 -> 1134.2687 | L41: =L33+L38 -> 1327.3095
B45: Balance Check | E45: =E24-E41 -> 0 | F45: =F24-F41 -> 0 | G45: =G24-G41 -> 0 | H45: =H24-H41 -> 0 | I45: =I24-I41 -> 0 | J45: =J24-J41 -> 0 | K45: =K24-K41 -> 0 | L45: =L24-L41 -> 0

Sheet Asset Schedule
A1: (Unless otherwise specified, all financials are in USD Mn) | E1: Historical | H1: Forecasted
C2: Units | E2: =PnL!E2 -> 2016 | F2: =PnL!F2 -> 2017 | G2: =PnL!G2 -> 2018 | H2: =PnL!H2 -> 2019 | I2: =PnL!I2 -> 2020 | J2: =PnL!J2 -> 2021 | K2: =PnL!K2 -> 2022 | L2: =PnL!L2 -> 2023
B4: Depreciation Method | C4: SLM
B5: Asset Life | C5: Years | E5: =Assumptions!E44 -> 10 | F5: =Assumptions!F44 -> 10 | G5: =Assumptions!G44 -> 10 | H5: =Assumptions!H44 -> 10 | I5: =Assumptions!I44 -> 10 | J5: =Assumptions!J44 -> 10 | K5: =Assumptions!K44 -> 10 | L5: =Assumptions!L44 -> 10
B6: Disposal of Assets | C6: USD Mn | E6: =Assumptions!E45 -> 0 | F6: =Assumptions!F45 -> 0 | G6: =Assumptions!G45 -> 0 | H6: =Assumptions!H45 -> 0 | I6: =Assumptions!I45 -> 0 | J6: =Assumptions!J45 -> 0 | K6: =Assumptions!K45 -> 0 | L6: =Assumptions!L45 -> 0
B8: Capex | C8: USD Mn | E8: =Assumptions!E43/10^6 -> 200 | F8: 0 | G8: =Assumptions!G43/10^6 -> 200 | H8: 0 | I8: =Assumptions!I43/10^6 -> 0 | J8: 0 | K8: 0 | L8: =Assumptions!L43/10^6 -> 0
A10: Depreciation Schedule
B12: =E2 -> 2016 | C12: {=TRANSPOSE(E8:L8)} -> 200 | E12: =IF(E$2>=$B12,$C12/$E$5,"") -> 20 | F12: =IF(F$2>=$B12,$C12/$E$5,"") -> 20 | G12: =IF(G$2>=$B12,$C12/$E$5,"") -> 20 | H12: =IF(H$2>=$B12,$C12/$E$5,"") -> 20 | I12: =IF(I$2>=$B12,$C12/$E$5,"") -> 20 | J12: =IF(J$2>=$B12,$C12/$E$5,"") -> 20 | K12: =IF(K$2>=$B12,$C12/$E$5,"") -> 20 | L12: =IF(L$2>=$B12,$C12/$E$5,"") -> 20
B13: =B12+1 -> 2017 | C13: 0 | E13: =IF(E$2>=$B13,$C13/$E$5,"") | F13: =IF(F$2>=$B13,$C13/$E$5,"") -> 0 | G13: =IF(G$2>=$B13,$C13/$E$5,"") -> 0 | H13: =IF(H$2>=$B13,$C13/$E$5,"") -> 0 | I13: =IF(I$2>=$B13,$C13/$E$5,"") -> 0 | J13: =IF(J$2>=$B13,$C13/$E$5,"") -> 0 | K13: =IF(K$2>=$B13,$C13/$E$5,"") -> 0 | L13: =IF(L$2>=$B13,$C13/$E$5,"") -> 0
B14: =B13+1 -> 2018 | C14: 200 | E14: =IF(E$2>=$B14,$C14/$E$5,"") | F14: =IF(F$2>=$B14,$C14/$E$5,"") | G14: =IF(G$2>=$B14,$C14/$E$5,"") -> 20 | H14: =IF(H$2>=$B14,$C14/$E$5,"") -> 20 | I14: =IF(I$2>=$B14,$C14/$E$5,"") -> 20 | J14: =IF(J$2>=$B14,$C14/$E$5,"") -> 20 | K14: =IF(K$2>=$B14,$C14/$E$5,"") -> 20 | L14: =IF(L$2>=$B14,$C14/$E$5,"") -> 20
B15: =B14+1 -> 2019 | C15: 0 | E15: =IF(E$2>=$B15,$C15/$E$5,"") | F15: =IF(F$2>=$B15,$C15/$E$5,"") | G15: =IF(G$2>=$B15,$C15/$E$5,"") | H15: =IF(H$2>=$B15,$C15/$E$5,"") -> 0 | I15: =IF(I$2>=$B15,$C15/$E$5,"") -> 0 | J15: =IF(J$2>=$B15,$C15/$E$5,"") -> 0 | K15: =IF(K$2>=$B15,$C15/$E$5,"") -> 0 | L15: =IF(L$2>=$B15,$C15/$E$5,"") -> 0
B16: =B15+1 -> 2020 | C16: 0 | E16: =IF(E$2>=$B16,$C16/$E$5,"") | F16: =IF(F$2>=$B16,$C16/$E$5,"") | G16: =IF(G$2>=$B16,$C16/$E$5,"") | H16: =IF(H$2>=$B16,$C16/$E$5,"") | I16: =IF(I$2>=$B16,$C16/$E$5,"") -> 0 | J16: =IF(J$2>=$B16,$C16/$E$5,"") -> 0 | K16: =IF(K$2>=$B16,$C16/$E$5,"") -> 0 | L16: =IF(L$2>=$B16,$C16/$E$5,"") -> 0
B17: =B16+1 -> 2021 | C17: 0 | E17: =IF(E$2>=$B17,$C17/$E$5,"") | F17: =IF(F$2>=$B17,$C17/$E$5,"") | G17: =IF(G$2>=$B17,$C17/$E$5,"") | H17: =IF(H$2>=$B17,$C17/$E$5,"") | I17: =IF(I$2>=$B17,$C17/$E$5,"") | J17: =IF(J$2>=$B17,$C17/$E$5,"") -> 0 | K17: =IF(K$2>=$B17,$C17/$E$5,"") -> 0 | L17: =IF(L$2>=$B17,$C17/$E$5,"") -> 0
B18: =B17+1 -> 2022 | C18: 0 | E18: =IF(E$2>=$B18,$C18/$E$5,"") | F18: =IF(F$2>=$B18,$C18/$E$5,"") | G18: =IF(G$2>=$B18,$C18/$E$5,"") | H18: =IF(H$2>=$B18,$C18/$E$5,"") | I18: =IF(I$2>=$B18,$C18/$E$5,"") | J18: =IF(J$2>=$B18,$C18/$E$5,"") | K18: =IF(K$2>=$B18,$C18/$E$5,"") -> 0 | L18: =IF(L$2>=$B18,$C18/$E$5,"") -> 0
B19: =B18+1 -> 2023 | C19: 0 | E19: =IF(E$2>=$B19,$C19/$E$5,"") | F19: =IF(F$2>=$B19,$C19/$E$5,"") | G19: =IF(G$2>=$B19,$C19/$E$5,"") | H19: =IF(H$2>=$B19,$C19/$E$5,"") | I19: =IF(I$2>=$B19,$C19/$E$5,"") | J19: =IF(J$2>=$B19,$C19/$E$5,"") | K19: =IF(K$2>=$B19,$C19/$E$5,"") | L19: =IF(L$2>=$B19,$C19/$E$5,"") -> 0
B20: Total Depreciation | E20: =SUM(E12:E19) -> 20 | F20: =SUM(F12:F19) -> 20 | G20: =SUM(G12:G19) -> 40 | H20: =SUM(H12:H19) -> 40 | I20: =SUM(I12:I19) -> 40 | J20: =SUM(J12:J19) -> 40 | K20: =SUM(K12:K19) -> 40 | L20: =SUM(L12:L19) -> 40
A22: Gross Block
B23: Opening Balance | E23: 0 | F23: =E26 -> 200 | G23: =F26 -> 200 | H23: =G26 -> 400 | I23: =H26 -> 400 | J23: =I26 -> 400 | K23: =J26 -> 400 | L23: =K26 -> 400
B24: Add: Capex | E24: =E8 -> 200 | F24: =F8 -> 0 | G24: =G8 -> 200 | H24: =H8 -> 0 | I24: =I8 -> 0 | J24: =J8 -> 0 | K24: =K8 -> 0 | L24: =L8 -> 0
B25: Less: Assets Sold/ Disposed | E25: =E6 -> 0 | F25: =F6 -> 0 | G25: =G6 -> 0 | H25: =H6 -> 0 | I25: =I6 -> 0 | J25: =J6 -> 0 | K25: =K6 -> 0 | L25: =L6 -> 0
B26: Closing Balance | E26: =E23+E24-E25 -> 200 | F26: =F23+F24-F25 -> 200 | G26: =G23+G24-G25 -> 400 | H26: =H23+H24-H25 -> 400 | I26: =I23+I24-I25 -> 400 | J26: =J23+J24-J25 -> 400 | K26: =K23+K24-K25 -> 400 | L26: =L23+L24-L25 -> 400
A28: Accumulated Depreciation
B29: Opening Balance | F29: =E31 -> 20 | G29: =F31 -> 40 | H29: =G31 -> 80 | I29: =H31 -> 120 | J29: =I31 -> 160 | K29: =J31 -> 200 | L29: =K31 -> 240
B30: Add: Depreciation during current year | E30: =E20 -> 20 | F30: =F20 -> 20 | G30: =G20 -> 40 | H30: =H20 -> 40 | I30: =I20 -> 40 | J30: =J20 -> 40 | K30: =K20 -> 40 | L30: =L20 -> 40
B31: Closing Balance | E31: =E29+E30 -> 20 | F31: =F29+F30 -> 40 | G31: =G29+G30 -> 80 | H31: =H29+H30 -> 120 | I31: =I29+I30 -> 160 | J31: =J29+J30 -> 200 | K31: =K29+K30 -> 240 | L31: =L29+L30 -> 280

Sheet Debt Schedule
A1: (Unless otherwise specified, all financials are in USD Mn) | E1: Historical | H1: Forecasted
E2: =PnL!E2 -> 2016 | F2: =PnL!F2 -> 2017 | G2: =PnL!G2 -> 2018 | H2: =PnL!H2 -> 2019 | I2: =PnL!I2 -> 2020 | J2: =PnL!J2 -> 2021 | K2: =PnL!K2 -> 2022 | L2: =PnL!L2 -> 2023
A4: Unsecured Loans
B5: Opening Balance | F5: =E8 -> 200 | G5: =F8 -> 190 | H5: =G8 -> 380 | I5: =H8 -> 360 | J5: =I8 -> 340 | K5: =J8 -> 320 | L5: =K8 -> 300
B6: Add: New Issued | E6: {=(Assumptions!E61:L61)/10^6} -> 0 | F6: 0 | G6: 200 | H6: 0 | I6: 0 | J6: 0 | K6: 0 | L6: 0 | N6: Assumptions
B7: Less: Repayments | E7: =0/(10^6) -> 0 | F7: =(Assumptions!F57)/(10^6) -> 10 | G7: =(Assumptions!G57)/(10^6) -> 10 | H7: =(Assumptions!H57)/(10^6) -> 20 | I7: =(Assumptions!I57)/(10^6) -> 20 | J7: =(Assumptions!J57)/(10^6) -> 20 | K7: =(Assumptions!K57)/(10^6) -> 20 | L7: =(Assumptions!L57)/(10^6) -> 20 | N7: Assumptions
B8: Closing Balance | E8: =BS!E16 -> 200 | F8: =F5+F6-F7 -> 190 | G8: =G5+G6-G7 -> 380 | H8: =H5+H6-H7 -> 360 | I8: =I5+I6-I7 -> 340 | J8: =J5+J6-J7 -> 320 | K8: =K5+K6-K7 -> 300 | L8: =L5+L6-L7 -> 280
B10: Average Loan Outstanding | H10: =AVERAGE(H5,H8) -> 370 | I10: =AVERAGE(I5,I8) -> 350 | J10: =AVERAGE(J5,J8) -> 330 | K10: =AVERAGE(K5,K8) -> 310 | L10: =AVERAGE(L5,L8) -> 290
B11: Interest Rate | H11: =Assumptions!H50 -> 0.1 | I11: =Assumptions!I50 -> 0.1 | J11: =Assumptions!J50 -> 0.1 | K11: =Assumptions!K50 -> 0.1 | L11: =Assumptions!L50 -> 0.1 | N11: Assumptions
B12: Interest Expense | H12: =H10*H11 -> 37 | I12: =I10*I11 -> 35 | J12: =J10*J11 -> 33 | K12: =K10*K11 -> 31 | L12: =L10*L11 -> 29
A14: Secured Loans
B15: Opening Balance | F15: =E18 -> 0 | G15: =F18 -> 0 | H15: =G18 -> 0 | I15: =H18 -> 0 | J15: =I18 -> 0 | K15: =J18 -> 0 | L15: =K18 -> 0
B16: Add: New Issued | F16: =Assumptions!F60/1000000 -> 0 | G16: =Assumptions!G60/1000000 -> 0 | H16: =Assumptions!H60/1000000 -> 0 | I16: =Assumptions!I60/1000000 -> 0 | J16: =Assumptions!J60/1000000 -> 0 | K16: =Assumptions!K60/1000000 -> 0 | L16: =Assumptions!L60/1000000 -> 0
B17: Less: Repayments | F17: =Assumptions!F56/1000000 -> 0 | G17: =Assumptions!G56/1000000 -> 0 | H17: =Assumptions!H56/1000000 -> 0 | I17: =Assumptions!I56/1000000 -> 0 | J17: =Assumptions!J56/1000000 -> 0 | K17: =Assumptions!K56/1000000 -> 0 | L17: =Assumptions!L56/1000000 -> 0
B18: Closing Balance | E18: =BS!E15 -> 0 | F18: =F15+F16-F17 -> 0 | G18: =G15+G16-G17 -> 0 | H18: =H15+H16-H17 -> 0 | I18: =I15+I16-I17 -> 0 | J18: =J15+J16-J17 -> 0 | K18: =K15+K16-K17 -> 0 | L18: =L15+L16-L17 -> 0
B20: Average Loan Outstanding | H20: =AVERAGE(G18:H18) -> 0 | I20: =AVERAGE(H18:I18) -> 0 | J20: =AVERAGE(I18:J18) -> 0 | K20: =AVERAGE(J18:K18) -> 0 | L20: =AVERAGE(K18:L18) -> 0
B21: Interest Rate | H21: =Assumptions!H49 -> 0.1 | I21: =Assumptions!I49 -> 0.1 | J21: =Assumptions!J49 -> 0.1 | K21: =Assumptions!K49 -> 0.1 | L21: =Assumptions!L49 -> 0.1
B22: Interest Expense | H22: =H21*H20 -> 0 | I22: =I21*I20 -> 0 | J22: =J21*J20 -> 0 | K22: =K21*K20 -> 0 | L22: =L21*L20 -> 0
B24: Total Interest Expense | H24: =H12+H22 -> 37 | I24: =I12+I22 -> 35 | J24: =J12+J22 -> 33 | K24: =K12+K22 -> 31 | L24: =L12+L22 -> 29
A27: Cash/ (Overdraft) | G27: =CF!G41 -> 169.36 | H27: =CF!H41 -> 337.97612 | I27: =CF!I41 -> 434.73906 | J27: =CF!J41 -> 531.96442 | K27: =CF!K41 -> 670.16044 | L27: =CF!L41 -> 860.60586 | N27: CF
B29: Interest rate on Cash Balance | H29: =Assumptions!H52 -> 0.06 | I29: =Assumptions!I52 -> 0.06 | J29: =Assumptions!J52 -> 0.06 | K29: =Assumptions!K52 -> 0.06 | L29: =Assumptions!L52 -> 0.06
B30: Interest rate on Overdraft | H30: =Assumptions!H53 -> 0.08 | I30: =Assumptions!I53 -> 0.08 | J30: =Assumptions!J53 -> 0.08 | K30: =Assumptions!K53 -> 0.08 | L30: =Assumptions!L53 -> 0.08
B32: Interest Earned/ (Expense) | H32: =H27*H29 -> 20.278567 | I32: =I27*I29 -> 26.084343 | J32: =J27*J29 -> 31.917865 | K32: =K27*K29 -> 40.209627 | L32: =L27*L29 -> 51.636351
B34: Net Interest Expense | H34: =H24-H32 -> 16.721433 | I34: =I24-I32 -> 8.9156566 | J34: =J24-J32 -> 1.0821347 | K34: =K24-K32 -> -9.2096266 | L34: =L24-L32 -> -22.636351

Sheet Equity Sch_Other
A1: (Unless otherwise specified, all financials are in USD Mn) | E1: Historical | H1: Forecasted
E2: =PnL!E2 -> 2016 | F2: =PnL!F2 -> 2017 | G2: =PnL!G2 -> 2018 | H2: =PnL!H2 -> 2019 | I2: =PnL!I2 -> 2020 | J2: =PnL!J2 -> 2021 | K2: =PnL!K2 -> 2022 | L2: =PnL!L2 -> 2023
A4: Paid-Up Capital
B5: Opening Balance | H5: =G7 -> 50 | I5: =H7 -> 50 | J5: =I7 -> 50 | K5: =J7 -> 50 | L5: =K7 -> 50
B6: Add: New Equity Raised | F6: =Assumptions!F63/10^6 -> 0 | G6: =Assumptions!G63/10^6 -> 0 | H6: =Assumptions!H63/10^6 -> 0 | I6: =Assumptions!I63/10^6 -> 0 | J6: =Assumptions!J63/10^6 -> 0 | K6: =Assumptions!K63/10^6 -> 0 | L6: =Assumptions!L63/10^6 -> 0
B7: Closing Balance | E7: =BS!E20 -> 50 | F7: =BS!F20 -> 50 | G7: =BS!G20 -> 50 | H7: =SUM(H5:H6) -> 50 | I7: =SUM(I5:I6) -> 50 | J7: =SUM(J5:J6) -> 50 | K7: =SUM(K5:K6) -> 50 | L7: =SUM(L5:L6) -> 50
A9: Retained Earnings
B10: Opening Balance | F10: =E13 -> 4.31 | G10: =F13 -> 16.06 | H10: =G13 -> 57.36 | I10: =H13 -> 152.93003 | J10: =I13 -> 213.30298 | K10: =J13 -> 281.60976 | L10: =K13 -> 397.33062
B11: Add: PAT | F11: =PnL!F22 -> 11.75 | G11: =PnL!G22 -> 41.3 | H11: =PnL!H22 -> 95.570035 | I11: =PnL!I22 -> 60.372947 | J11: =PnL!J22 -> 68.306778 | K11: =PnL!K22 -> 115.72086 | L11: =PnL!L22 -> 169.03337 | N11: P&L
B12: Less: Dividends Paid | F12: =Assumptions!F65/10^6 -> 0 | G12: =Assumptions!G65/10^6 -> 0 | H12: =Assumptions!H65/10^6 -> 0 | I12: =Assumptions!I65/10^6 -> 0 | J12: =Assumptions!J65/10^6 -> 0 | K12: =Assumptions!K65/10^6 -> 0 | L12: =Assumptions!L65/10^6 -> 0
B13: Closing Balance | E13: =PnL!E22 -> 4.31 | F13: =F10+F11-F12 -> 16.06 | G13: =G10+G11-G12 -> 57.36 | H13: =H10+H11-H12 -> 152.93003 | I13: =I10+I11-I12 -> 213.30298 | J13: =J10+J11-J12 -> 281.60976 | K13: =K10+K11-K12 -> 397.33062 | L13: =L10+L11-L12 -> 566.36399
E16: Note: In PDF, this sheet is named as "Other Calc". Have renamed it to "Equity Schedule" for better understanding

Sheet CF
A1: (Unless otherwise specified, all financials are in USD Mn) | E1: Historical | H1: Forecasted
E2: =PnL!E2 -> 2016 | F2: =PnL!F2 -> 2017 | G2: =PnL!G2 -> 2018 | H2: =PnL!H2 -> 2019 | I2: =PnL!I2 -> 2020 | J2: =PnL!J2 -> 2021 | K2: =PnL!K2 -> 2022 | L2: =PnL!L2 -> 2023
A4: Cashflow from Operating Activities
B5: PAT | F5: =PnL!F22 -> 11.75 | G5: =PnL!G22 -> 41.3 | H5: =PnL!H22 -> 95.570035 | I5: =PnL!I22 -> 60.372947 | J5: =PnL!J22 -> 68.306778 | K5: =PnL!K22 -> 115.72086 | L5: =PnL!L22 -> 169.03337 | N5: P&L
B6: Add: Depreciation | F6: =PnL!F17 -> 20 | G6: =PnL!G17 -> 40 | H6: =PnL!H17 -> 40 | I6: =PnL!I17 -> 40 | J6: =PnL!J17 -> 40 | K6: =PnL!K17 -> 40 | L6: =PnL!L17 -> 40 | N6: P&L
B7: Add: Interest Expense | F7: =PnL!F19 -> 19.5 | G7: =PnL!G19 -> 28.5 | H7: =PnL!H19 -> 16.721433 | I7: =PnL!I19 -> 8.9156566 | J7: =PnL!J19 -> 1.0821347 | K7: =PnL!K19 -> -9.2096266 | L7: =PnL!L19 -> -22.636351 | N7: P&L
B9: Net Change in Working Capital
B10: ="Add: "&BS!B9 -> Add: Accounts payable | F10: =BS!F9-BS!E9 -> 72.67 | G10: =BS!G9-BS!F9 -> 49.58 | H10: =BS!H9-BS!G9 -> -54.959178 | I10: =BS!I9-BS!H9 -> 10.165163 | J10: =BS!J9-BS!I9 -> 11.018846 | K10: =BS!K9-BS!J9 -> 11.944223 | L10: =BS!L9-BS!K9 -> 12.947314 | N10: BS
B11: ="Add: "&BS!B10 -> Add: Accrued liabilities | F11: =BS!F10-BS!E10 -> 37.68 | G11: =BS!G10-BS!F10 -> 46.61 | H11: =BS!H10-BS!G10 -> -46.278319 | I11: =BS!I10-BS!H10 -> 7.2829977 | J11: =BS!J10-BS!I10 -> 7.8946331 | K11: =BS!K10-BS!J10 -> 8.5576345 | L11: =BS!L10-BS!K10 -> 9.2763156 | N11: BS
B12: ="Add: "&BS!B11 -> Add: Deferred revenue | F12: =BS!F11-BS!E11 -> 61.04 | G12: =BS!G11-BS!F11 -> 27.22 | H12: =BS!H11-BS!G11 -> -10.769524 | I12: =BS!I11-BS!H11 -> -6.7045257 | J12: =BS!J11-BS!I11 -> 6.5167838 | K12: =BS!K11-BS!J11 -> 18.269376 | L12: =BS!L11-BS!K11 -> 21.783768 | N12: BS
B13: ="Less: "&BS!B30 -> Less: Accounts receivable | F13: =BS!F30-BS!E30 -> 42.47 | G13: =BS!G30-BS!F30 -> 102.33 | H13: =BS!H30-BS!G30 -> -53.866447 | I13: =BS!I30-BS!H30 -> -11.008002 | J13: =BS!J30-BS!I30 -> 10.699753 | K13: =BS!K30-BS!J30 -> 29.996056 | L13: =BS!L30-BS!K30 -> 35.766253 | N13: BS
B14: ="Less: "&BS!B31 -> Less: Inventories,net | F14: =BS!F31-BS!E31 -> 51.58 | G14: =BS!G31-BS!F31 -> 63.01 | H14: =BS!H31-BS!G31 -> -111.15666 | I14: =BS!I31-BS!H31 -> 5.3616455 | J14: =BS!J31-BS!I31 -> 5.8119234 | K14: =BS!K31-BS!J31 -> 6.3000161 | L14: =BS!L31-BS!K31 -> 6.8290995 | N14: BS
B15: ="Less: "&BS!B32 -> Less: Prepaid Expenses and other current assets | F15: =BS!F32-BS!E32 -> 0.25 | G15: =BS!G32-BS!F32 -> 0.03 | H15: =BS!H32-BS!G32 -> -0.03 | I15: =BS!I32-BS!H32 -> 0 | J15: =BS!J32-BS!I32 -> 0 | K15: =BS!K32-BS!J32 -> 0 | L15: =BS!L32-BS!K32 -> 0 | N15: BS
B16: Net Change in Working Capital | F16: =F10+F11+F12-F13-F14-F15 -> 77.09 | G16: =G10+G11+G12-G13-G14-G15 -> -41.96 | H16: =H10+H11+H12-H13-H14-H15 -> 53.046084 | I16: =I10+I11+I12-I13-I14-I15 -> 16.389992 | J16: =J10+J11+J12-J13-J14-J15 -> 8.9185868 | K16: =K10+K11+K12-K13-K14-K15 -> 2.4751614 | L16: =L10+L11+L12-L13-L14-L15 -> 1.4120453
B18: Cashflow from Operations | F18: =F5+F6+F7+F16 -> 128.34 | G18: =G5+G6+G7+G16 -> 67.84 | H18: =H5+H6+H7+H16 -> 205.33755 | I18: =I5+I6+I7+I16 -> 125.67859 | J18: =J5+J6+J7+J16 -> 118.3075 | K18: =K5+K6+K7+K16 -> 148.9864 | L18: =L5+L6+L7+L16 -> 187.80906
A20: Cashflow from Investment Activities
B21: Less: Capex | F21: =Assumptions!F43/10^6 -> 0 | G21: =Assumptions!G43/10^6 -> 200 | H21: =Assumptions!H43/10^6 -> 0 | I21: =Assumptions!I43/10^6 -> 0 | J21: =Assumptions!J43/10^6 -> 0 | K21: =Assumptions!K43/10^6 -> 0 | L21: =Assumptions!L43/10^6 -> 0 | N21: Asset Schedule
B22: Add: Disposal of Assets | F22: =Assumptions!F45 -> 0 | G22: =Assumptions!G45 -> 0 | H22: =Assumptions!H45 -> 0 | I22: =Assumptions!I45 -> 0 | J22: =Assumptions!J45 -> 0 | K22: =Assumptions!K45 -> 0 | L22: =Assumptions!L45 -> 0 | N22: Asset Schedule
B23: Less: Increase in WIP
B24: Cashflow from Investment Activities | F24: =-F21 -> 0 | G24: =-G21 -> -200 | H24: =-H21 -> 0 | I24: =-I21 -> 0 | J24: =-J21 -> 0 | K24: =-K21 -> 0 | L24: =-L21 -> 0
A26: Cashflow from Financing Activities
B27: Add: New Equity Raised | F27: ='Equity Sch_Other'!F6 -> 0 | G27: ='Equity Sch_Other'!G6 -> 0 | H27: ='Equity Sch_Other'!H6 -> 0 | I27: ='Equity Sch_Other'!I6 -> 0 | J27: ='Equity Sch_Other'!J6 -> 0 | K27: ='Equity Sch_Other'!K6 -> 0 | L27: ='Equity Sch_Other'!L6 -> 0 | N27: Equity Schedule
B28: Add: New Secured Loans Raised | F28: ='Debt Schedule'!F16 -> 0 | G28: ='Debt Schedule'!G16 -> 0 | H28: ='Debt Schedule'!H16 -> 0 | I28: ='Debt Schedule'!I16 -> 0 | J28: ='Debt Schedule'!J16 -> 0 | K28: ='Debt Schedule'!K16 -> 0 | L28: ='Debt Schedule'!L16 -> 0 | N28: Debt Schedule
B29: Add: New Unsecured Loans Raised | F29: ='Debt Schedule'!F6 -> 0 | G29: ='Debt Schedule'!G6 -> 200 | H29: ='Debt Schedule'!H6 -> 0 | I29: ='Debt Schedule'!I6 -> 0 | J29: ='Debt Schedule'!J6 -> 0 | K29: ='Debt Schedule'!K6 -> 0 | L29: ='Debt Schedule'!L6 -> 0 | N29: Debt Schedule
B30: Less: Secured Loans Repaid | F30: ='Debt Schedule'!F17 -> 0 | G30: ='Debt Schedule'!G17 -> 0 | H30: ='Debt Schedule'!H17 -> 0 | I30: ='Debt Schedule'!I17 -> 0 | J30: ='Debt Schedule'!J17 -> 0 | K30: ='Debt Schedule'!K17 -> 0 | L30: ='Debt Schedule'!L17 -> 0 | N30: Debt Schedule
B31: Less: Unsecured Loans Repaid | F31: ='Debt Schedule'!F7 -> 10 | G31: ='Debt Schedule'!G7 -> 10 | H31: ='Debt Schedule'!H7 -> 20 | I31: ='Debt Schedule'!I7 -> 20 | J31: ='Debt Schedule'!J7 -> 20 | K31: ='Debt Schedule'!K7 -> 20 | L31: ='Debt Schedule'!L7 -> 20 | N31: Debt Schedule
B32: Less: Dividends Paid | F32: ='Equity Sch_Other'!F12 -> 0 | G32: ='Equity Sch_Other'!G12 -> 0 | H32: ='Equity Sch_Other'!H12 -> 0 | I32: ='Equity Sch_Other'!I12 -> 0 | J32: ='Equity Sch_Other'!J12 -> 0 | K32: ='Equity Sch_Other'!K12 -> 0 | L32: ='Equity Sch_Other'!L12 -> 0 | N32: Equity Schedule
B33: Less: Interest Expense | F33: =PnL!F19 -> 19.5 | G33: =PnL!G19 -> 28.5 | H33: =PnL!H19 -> 16.721433 | I33: =PnL!I19 -> 8.9156566 | J33: =PnL!J19 -> 1.0821347 | K33: =PnL!K19 -> -9.2096266 | L33: =PnL!L19 -> -22.636351 | N33: P&L
B34: Cashflow from Financing Activities | F34: =F27+F28+F29-F30-F31-F32-F33 -> -29.5 | G34: =G27+G28+G29-G30-G31-G32-G33 -> 161.5 | H34: =H27+H28+H29-H30-H31-H32-H33 -> -36.721433 | I34: =I27+I28+I29-I30-I31-I32-I33 -> -28.915657 | J34: =J27+J28+J29-J30-J31-J32-J33 -> -21.082135 | K34: =K27+K28+K29-K30-K31-K32-K33 -> -10.790373 | L34: =L27+L28+L29-L30-L31-L32-L33 -> 2.6363514
B36: Net Cashflow | F36: =F18+F24+F34 -> 98.84 | G36: =G18+G24+G34 -> 29.34 | H36: =H18+H24+H34 -> 168.61612 | I36: =I18+I24+I34 -> 96.762938 | J36: =J18+J24+J34 -> 97.225365 | K36: =K18+K24+K34 -> 138.19602 | L36: =L18+L24+L34 -> 190.44541
A38: Cash Balance
B39: Opening Balance | F39: =E41 -> 41.18 | G39: =F41 -> 140.02 | H39: =G41 -> 169.36 | I39: =H41 -> 337.97612 | J39: =I41 -> 434.73906 | K39: =J41 -> 531.96442 | L39: =K41 -> 670.16044
B40: Net Cashflow | F40: =F36 -> 98.84 | G40: =G36 -> 29.34 | H40: =H36 -> 168.61612 | I40: =I36 -> 96.762938 | J40: =J36 -> 97.225365 | K40: =K36 -> 138.19602 | L40: =L36 -> 190.44541
B41: Closing Balance | E41: =BS!E29 -> 41.18 | F41: =SUM(F39:F40) -> 140.02 | G41: =SUM(G39:G40) -> 169.36 | H41: =SUM(H39:H40) -> 337.97612 | I41: =SUM(I39:I40) -> 434.73906 | J41: =SUM(J39:J40) -> 531.96442 | K41: =SUM(K39:K40) -> 670.16044 | L41: =SUM(L39:L40) -> 860.60586
