Workbook
Name data: Financials!$C$9:$AU$232
Name data_column: Financials!$C$1:$AU$1
Name data_row: Financials!$A$9:$A$232
Name rCP: Valuation!$H$23

Sheet Summary
A1: Summary | C1: =Financials!G1 -> FY2016 | D1: =Financials!L1 -> FY2017 | E1: =Financials!Q1 -> FY2018 | F1: =Financials!V1 -> FY2019 | G1: =Financials!AA1 -> FY2020 | H1: =Financials!AF1 -> FY2021 | I1: =Financials!AK1 -> FY2022 | J1: =Financials!AP1 -> FY2023 | K1: =Financials!AU1 -> FY2024
C2: =Financials!G3 -> A | D2: =Financials!L3 -> A | E2: =Financials!Q3 -> A | F2: =Financials!V3 -> F | G2: =Financials!AA3 -> F | H2: =Financials!AF3 -> F | I2: =Financials!AK3 -> F | J2: =Financials!AP3 -> F | K2: =Financials!AU3 -> F
A4: Income Statement
A6: Revenue | B6: INR Mn | C6: =INDEX(data,MATCH($A6,data_row,0),MATCH(C$1,data_column,0)) -> 53694.5 | D6: =INDEX(data,MATCH($A6,data_row,0),MATCH(D$1,data_column,0)) -> 56167.9 | E6: =INDEX(data,MATCH($A6,data_row,0),MATCH(E$1,data_column,0)) -> 60870 | F6: =INDEX(data,MATCH($A6,data_row,0),MATCH(F$1,data_column,0)) -> 72138.537 | G6: =INDEX(data,MATCH($A6,data_row,0),MATCH(G$1,data_column,0)) -> 77147.989 | H6: =INDEX(data,MATCH($A6,data_row,0),MATCH(H$1,data_column,0)) -> 84365.219 | I6: =INDEX(data,MATCH($A6,data_row,0),MATCH(I$1,data_column,0)) -> 90224.691 | J6: =INDEX(data,MATCH($A6,data_row,0),MATCH(J$1,data_column,0)) -> 96507.612 | K6: =INDEX(data,MATCH($A6,data_row,0),MATCH(K$1,data_column,0)) -> 103245.54
A7: Gross Profit | B7: INR Mn | C7: =INDEX(data,MATCH($A7,data_row,0),MATCH(C$1,data_column,0)) -> 27831.5 | D7: =INDEX(data,MATCH($A7,data_row,0),MATCH(D$1,data_column,0)) -> 29772.3 | E7: =INDEX(data,MATCH($A7,data_row,0),MATCH(E$1,data_column,0)) -> 31993.5 | F7: =INDEX(data,MATCH($A7,data_row,0),MATCH(F$1,data_column,0)) -> 35544.92 | G7: =INDEX(data,MATCH($A7,data_row,0),MATCH(G$1,data_column,0)) -> 39345.475 | H7: =INDEX(data,MATCH($A7,data_row,0),MATCH(H$1,data_column,0)) -> 43026.262 | I7: =INDEX(data,MATCH($A7,data_row,0),MATCH(I$1,data_column,0)) -> 46916.84 | J7: =INDEX(data,MATCH($A7,data_row,0),MATCH(J$1,data_column,0)) -> 50183.958 | K7: =INDEX(data,MATCH($A7,data_row,0),MATCH(K$1,data_column,0)) -> 53687.682
A8: EBITDA | B8: INR Mn | C8: =INDEX(data,MATCH($A8,data_row,0),MATCH(C$1,data_column,0)) -> 11787.1 | D8: =INDEX(data,MATCH($A8,data_row,0),MATCH(D$1,data_column,0)) -> 12656 | E8: =INDEX(data,MATCH($A8,data_row,0),MATCH(E$1,data_column,0)) -> 13412.2 | F8: =INDEX(data,MATCH($A8,data_row,0),MATCH(F$1,data_column,0)) -> 14323.98 | G8: =INDEX(data,MATCH($A8,data_row,0),MATCH(G$1,data_column,0)) -> 15439.733 | H8: =INDEX(data,MATCH($A8,data_row,0),MATCH(H$1,data_column,0)) -> 16819.741 | I8: =INDEX(data,MATCH($A8,data_row,0),MATCH(I$1,data_column,0)) -> 17984.137 | J8: =INDEX(data,MATCH($A8,data_row,0),MATCH(J$1,data_column,0)) -> 19236.753 | K8: =INDEX(data,MATCH($A8,data_row,0),MATCH(K$1,data_column,0)) -> 20580.356
A9: EBIT | B9: INR Mn | C9: =INDEX(data,MATCH($A9,data_row,0),MATCH(C$1,data_column,0)) -> 10455.8 | D9: =INDEX(data,MATCH($A9,data_row,0),MATCH(D$1,data_column,0)) -> 11504.6 | E9: =INDEX(data,MATCH($A9,data_row,0),MATCH(E$1,data_column,0)) -> 12213.4 | F9: =INDEX(data,MATCH($A9,data_row,0),MATCH(F$1,data_column,0)) -> 13062.091 | G9: =INDEX(data,MATCH($A9,data_row,0),MATCH(G$1,data_column,0)) -> 14139.303 | H9: =INDEX(data,MATCH($A9,data_row,0),MATCH(H$1,data_column,0)) -> 15447.223 | I9: =INDEX(data,MATCH($A9,data_row,0),MATCH(I$1,data_column,0)) -> 16546.54 | J9: =INDEX(data,MATCH($A9,data_row,0),MATCH(J$1,data_column,0)) -> 17739.964 | K9: =INDEX(data,MATCH($A9,data_row,0),MATCH(K$1,data_column,0)) -> 19020.737
A10: PAT to equity shareholders | B10: INR Mn | C10: =INDEX(data,MATCH($A10,data_row,0),MATCH(C$1,data_column,0)) -> 7555.5 | D10: =INDEX(data,MATCH($A10,data_row,0),MATCH(D$1,data_column,0)) -> 8599.9 | E10: =INDEX(data,MATCH($A10,data_row,0),MATCH(E$1,data_column,0)) -> 9623.5 | F10: =INDEX(data,MATCH($A10,data_row,0),MATCH(F$1,data_column,0)) -> 9289.6963 | G10: =INDEX(data,MATCH($A10,data_row,0),MATCH(G$1,data_column,0)) -> 10405.061 | H10: =INDEX(data,MATCH($A10,data_row,0),MATCH(H$1,data_column,0)) -> 11307.301 | I10: =INDEX(data,MATCH($A10,data_row,0),MATCH(I$1,data_column,0)) -> 12064.544 | J10: =INDEX(data,MATCH($A10,data_row,0),MATCH(J$1,data_column,0)) -> 12886.05 | K10: =INDEX(data,MATCH($A10,data_row,0),MATCH(K$1,data_column,0)) -> 13767.551
A11: Adjusted PAT | B11: INR Mn | C11: =Financials!G49-Financials!G38 -> 7603.6 | D11: =Financials!L49-Financials!L38 -> 8658 | E11: =Financials!Q49-Financials!Q38 -> 9623.5 | F11: =Financials!V49-Financials!V38 -> 9289.6963 | G11: =Financials!AA49-Financials!AA38 -> 10405.061 | H11: =Financials!AF49-Financials!AF38 -> 11307.301 | I11: =Financials!AK49-Financials!AK38 -> 12064.544 | J11: =Financials!AP49-Financials!AP38 -> 12886.05 | K11: =Financials!AU49-Financials!AU38 -> 13767.551
A12: Adjusted diluted EPS | B12: INR/share | C12: =C11/Financials!G55 -> 14.830505 | D12: =D11/Financials!L55 -> 16.881397 | E12: =E11/Financials!Q55 -> 18.813352 | F12: =F11/Financials!V55 -> 18.289504 | G12: =G11/Financials!AA55 -> 20.482404 | H12: =H11/Financials!AF55 -> 22.258466 | I12: =I11/Financials!AK55 -> 23.749102 | J12: =J11/Financials!AP55 -> 25.36624 | K12: =K11/Financials!AU55 -> 27.101479
A14: Balance Sheet
A16: Cash and Cash Equivalents | B16: INR Mn | C16: =INDEX(data,MATCH($A16,data_row,0),MATCH(C$1,data_column,0)) -> 1319.4 | D16: =INDEX(data,MATCH($A16,data_row,0),MATCH(D$1,data_column,0)) -> 999.4 | E16: =INDEX(data,MATCH($A16,data_row,0),MATCH(E$1,data_column,0)) -> 1635.8 | F16: =INDEX(data,MATCH($A16,data_row,0),MATCH(F$1,data_column,0)) -> 7413.7113 | G16: =INDEX(data,MATCH($A16,data_row,0),MATCH(G$1,data_column,0)) -> 13113.522 | H16: =INDEX(data,MATCH($A16,data_row,0),MATCH(H$1,data_column,0)) -> 18935.507 | I16: =INDEX(data,MATCH($A16,data_row,0),MATCH(I$1,data_column,0)) -> 26211.863 | J16: =INDEX(data,MATCH($A16,data_row,0),MATCH(J$1,data_column,0)) -> 33424.517 | K16: =INDEX(data,MATCH($A16,data_row,0),MATCH(K$1,data_column,0)) -> 41388.039
A17: Fixed Assets | B17: INR Mn | C17: =INDEX(data,MATCH($A17,data_row,0),MATCH(C$1,data_column,0)) -> 15074.8 | D17: =INDEX(data,MATCH($A17,data_row,0),MATCH(D$1,data_column,0)) -> 9368.3 | E17: =INDEX(data,MATCH($A17,data_row,0),MATCH(E$1,data_column,0)) -> 10303.2 | F17: =INDEX(data,MATCH($A17,data_row,0),MATCH(F$1,data_column,0)) -> 10941.311 | G17: =INDEX(data,MATCH($A17,data_row,0),MATCH(G$1,data_column,0)) -> 11740.881 | H17: =INDEX(data,MATCH($A17,data_row,0),MATCH(H$1,data_column,0)) -> 12468.363 | I17: =INDEX(data,MATCH($A17,data_row,0),MATCH(I$1,data_column,0)) -> 13130.766 | J17: =INDEX(data,MATCH($A17,data_row,0),MATCH(J$1,data_column,0)) -> 13833.977 | K17: =INDEX(data,MATCH($A17,data_row,0),MATCH(K$1,data_column,0)) -> 14474.359
A18: Total Assets | B18: INR Mn | C18: =INDEX(data,MATCH($A18,data_row,0),MATCH(C$1,data_column,0)) -> 39081.9 | D18: =INDEX(data,MATCH($A18,data_row,0),MATCH(D$1,data_column,0)) -> 47741.9 | E18: =INDEX(data,MATCH($A18,data_row,0),MATCH(E$1,data_column,0)) -> 52044.6 | F18: =INDEX(data,MATCH($A18,data_row,0),MATCH(F$1,data_column,0)) -> 59853.76 | G18: =INDEX(data,MATCH($A18,data_row,0),MATCH(G$1,data_column,0)) -> 67736.621 | H18: =INDEX(data,MATCH($A18,data_row,0),MATCH(H$1,data_column,0)) -> 76774.048 | I18: =INDEX(data,MATCH($A18,data_row,0),MATCH(I$1,data_column,0)) -> 86029.828 | J18: =INDEX(data,MATCH($A18,data_row,0),MATCH(J$1,data_column,0)) -> 95943.539 | K18: =INDEX(data,MATCH($A18,data_row,0),MATCH(K$1,data_column,0)) -> 106548.37
A19: Short term borrowings | B19: INR Mn | C19: =INDEX(data,MATCH($A19,data_row,0),MATCH(C$1,data_column,0)) -> 749.2 | D19: =INDEX(data,MATCH($A19,data_row,0),MATCH(D$1,data_column,0)) -> 926.6 | E19: =INDEX(data,MATCH($A19,data_row,0),MATCH(E$1,data_column,0)) -> 1154.4 | F19: =INDEX(data,MATCH($A19,data_row,0),MATCH(F$1,data_column,0)) -> 1154.4 | G19: =INDEX(data,MATCH($A19,data_row,0),MATCH(G$1,data_column,0)) -> 1154.4 | H19: =INDEX(data,MATCH($A19,data_row,0),MATCH(H$1,data_column,0)) -> 1154.4 | I19: =INDEX(data,MATCH($A19,data_row,0),MATCH(I$1,data_column,0)) -> 1154.4 | J19: =INDEX(data,MATCH($A19,data_row,0),MATCH(J$1,data_column,0)) -> 1154.4 | K19: =INDEX(data,MATCH($A19,data_row,0),MATCH(K$1,data_column,0)) -> 1154.4
A20: Long term borrowings | B20: INR Mn | C20: =INDEX(data,MATCH($A20,data_row,0),MATCH(C$1,data_column,0)) -> 93.6 | D20: =INDEX(data,MATCH($A20,data_row,0),MATCH(D$1,data_column,0)) -> 48.5 | E20: =INDEX(data,MATCH($A20,data_row,0),MATCH(E$1,data_column,0)) -> 71.1 | F20: =INDEX(data,MATCH($A20,data_row,0),MATCH(F$1,data_column,0)) -> 71.1 | G20: =INDEX(data,MATCH($A20,data_row,0),MATCH(G$1,data_column,0)) -> 71.1 | H20: =INDEX(data,MATCH($A20,data_row,0),MATCH(H$1,data_column,0)) -> 71.1 | I20: =INDEX(data,MATCH($A20,data_row,0),MATCH(I$1,data_column,0)) -> 71.1 | J20: =INDEX(data,MATCH($A20,data_row,0),MATCH(J$1,data_column,0)) -> 71.1 | K20: =INDEX(data,MATCH($A20,data_row,0),MATCH(K$1,data_column,0)) -> 71.1
A21: Total Liabilities | B21: INR Mn | C21: =INDEX(data,MATCH($A21,data_row,0),MATCH(C$1,data_column,0)) -> 10825.5 | D21: =INDEX(data,MATCH($A21,data_row,0),MATCH(D$1,data_column,0)) -> 11759.6 | E21: =INDEX(data,MATCH($A21,data_row,0),MATCH(E$1,data_column,0)) -> 14554.1 | F21: =INDEX(data,MATCH($A21,data_row,0),MATCH(F$1,data_column,0)) -> 16093.724 | G21: =INDEX(data,MATCH($A21,data_row,0),MATCH(G$1,data_column,0)) -> 16642.244 | H21: =INDEX(data,MATCH($A21,data_row,0),MATCH(H$1,data_column,0)) -> 17812.655 | I21: =INDEX(data,MATCH($A21,data_row,0),MATCH(I$1,data_column,0)) -> 18743.385 | J21: =INDEX(data,MATCH($A21,data_row,0),MATCH(J$1,data_column,0)) -> 19760.917 | K21: =INDEX(data,MATCH($A21,data_row,0),MATCH(K$1,data_column,0)) -> 20859.731
A22: Shareholder Equity | B22: INR Mn | C22: =INDEX(data,MATCH($A22,data_row,0),MATCH(C$1,data_column,0)) -> 512.7 | D22: =INDEX(data,MATCH($A22,data_row,0),MATCH(D$1,data_column,0)) -> 512.7 | E22: =INDEX(data,MATCH($A22,data_row,0),MATCH(E$1,data_column,0)) -> 507.8 | F22: =INDEX(data,MATCH($A22,data_row,0),MATCH(F$1,data_column,0)) -> 507.8 | G22: =INDEX(data,MATCH($A22,data_row,0),MATCH(G$1,data_column,0)) -> 507.8 | H22: =INDEX(data,MATCH($A22,data_row,0),MATCH(H$1,data_column,0)) -> 507.8 | I22: =INDEX(data,MATCH($A22,data_row,0),MATCH(I$1,data_column,0)) -> 507.8 | J22: =INDEX(data,MATCH($A22,data_row,0),MATCH(J$1,data_column,0)) -> 507.8 | K22: =INDEX(data,MATCH($A22,data_row,0),MATCH(K$1,data_column,0)) -> 507.8
A23: Total Equity | B23: INR Mn | C23: =INDEX(data,MATCH($A23,data_row,0),MATCH(C$1,data_column,0)) -> 28256.4 | D23: =INDEX(data,MATCH($A23,data_row,0),MATCH(D$1,data_column,0)) -> 35982.3 | E23: =INDEX(data,MATCH($A23,data_row,0),MATCH(E$1,data_column,0)) -> 37490.5 | F23: =INDEX(data,MATCH($A23,data_row,0),MATCH(F$1,data_column,0)) -> 43760.036 | G23: =INDEX(data,MATCH($A23,data_row,0),MATCH(G$1,data_column,0)) -> 51094.377 | H23: =INDEX(data,MATCH($A23,data_row,0),MATCH(H$1,data_column,0)) -> 58961.393 | I23: =INDEX(data,MATCH($A23,data_row,0),MATCH(I$1,data_column,0)) -> 67286.443 | J23: =INDEX(data,MATCH($A23,data_row,0),MATCH(J$1,data_column,0)) -> 76182.622 | K23: =INDEX(data,MATCH($A23,data_row,0),MATCH(K$1,data_column,0)) -> 85688.638
A25: Cash Flow
A27: Cash flow from operations | B27: INR Mn | C27: =INDEX(data,MATCH($A27,data_row,0),MATCH(C$1,data_column,0)) -> 9074.7 | D27: =INDEX(data,MATCH($A27,data_row,0),MATCH(D$1,data_column,0)) -> 7937.5 | E27: =INDEX(data,MATCH($A27,data_row,0),MATCH(E$1,data_column,0)) -> 7964.3 | F27: =INDEX(data,MATCH($A27,data_row,0),MATCH(F$1,data_column,0)) -> 10724.711 | G27: =INDEX(data,MATCH($A27,data_row,0),MATCH(G$1,data_column,0)) -> 10912.319 | H27: =INDEX(data,MATCH($A27,data_row,0),MATCH(H$1,data_column,0)) -> 11407.681 | I27: =INDEX(data,MATCH($A27,data_row,0),MATCH(I$1,data_column,0)) -> 13164.302 | J27: =INDEX(data,MATCH($A27,data_row,0),MATCH(J$1,data_column,0)) -> 13454.276 | K27: =INDEX(data,MATCH($A27,data_row,0),MATCH(K$1,data_column,0)) -> 14480.349
A28: Capital expenditure fixed assets | B28: INR Mn | C28: =INDEX(data,MATCH($A28,data_row,0),MATCH(C$1,data_column,0)) -> -1704.3 | D28: =INDEX(data,MATCH($A28,data_row,0),MATCH(D$1,data_column,0)) -> -1330.6 | E28: =INDEX(data,MATCH($A28,data_row,0),MATCH(E$1,data_column,0)) -> -1768.3 | F28: =INDEX(data,MATCH($A28,data_row,0),MATCH(F$1,data_column,0)) -> -1900 | G28: =INDEX(data,MATCH($A28,data_row,0),MATCH(G$1,data_column,0)) -> -2100 | H28: =INDEX(data,MATCH($A28,data_row,0),MATCH(H$1,data_column,0)) -> -2100 | I28: =INDEX(data,MATCH($A28,data_row,0),MATCH(I$1,data_column,0)) -> -2100 | J28: =INDEX(data,MATCH($A28,data_row,0),MATCH(J$1,data_column,0)) -> -2200 | K28: =INDEX(data,MATCH($A28,data_row,0),MATCH(K$1,data_column,0)) -> -2200
A29: Cash flow from investing activities | B29: INR Mn | C29: =INDEX(data,MATCH($A29,data_row,0),MATCH(C$1,data_column,0)) -> -4911.4 | D29: =INDEX(data,MATCH($A29,data_row,0),MATCH(D$1,data_column,0)) -> -8789.7 | E29: =INDEX(data,MATCH($A29,data_row,0),MATCH(E$1,data_column,0)) -> 392.6 | F29: =INDEX(data,MATCH($A29,data_row,0),MATCH(F$1,data_column,0)) -> -1900 | G29: =INDEX(data,MATCH($A29,data_row,0),MATCH(G$1,data_column,0)) -> -2100 | H29: =INDEX(data,MATCH($A29,data_row,0),MATCH(H$1,data_column,0)) -> -2100 | I29: =INDEX(data,MATCH($A29,data_row,0),MATCH(I$1,data_column,0)) -> -2100 | J29: =INDEX(data,MATCH($A29,data_row,0),MATCH(J$1,data_column,0)) -> -2200 | K29: =INDEX(data,MATCH($A29,data_row,0),MATCH(K$1,data_column,0)) -> -2200
A30: Dividend paid | B30: INR Mn | C30: =INDEX(data,MATCH($A30,data_row,0),MATCH(C$1,data_column,0)) -> -4032.2 | D30: =INDEX(data,MATCH($A30,data_row,0),MATCH(D$1,data_column,0)) -> -316.3 | E30: =INDEX(data,MATCH($A30,data_row,0),MATCH(E$1,data_column,0)) -> -2930 | F30: =INDEX(data,MATCH($A30,data_row,0),MATCH(F$1,data_column,0)) -> -3046.8 | G30: =INDEX(data,MATCH($A30,data_row,0),MATCH(G$1,data_column,0)) -> -3112.5078 | H30: =INDEX(data,MATCH($A30,data_row,0),MATCH(H$1,data_column,0)) -> -3485.6956 | I30: =INDEX(data,MATCH($A30,data_row,0),MATCH(I$1,data_column,0)) -> -3787.9457 | J30: =INDEX(data,MATCH($A30,data_row,0),MATCH(J$1,data_column,0)) -> -4041.6222 | K30: =INDEX(data,MATCH($A30,data_row,0),MATCH(K$1,data_column,0)) -> -4316.8267
A31: Debt issuance/ repayment | B31: INR Mn | C31: =INDEX(data,MATCH($A31,data_row,0),MATCH(C$1,data_column,0)) -> 116.2 | D31: =INDEX(data,MATCH($A31,data_row,0),MATCH(D$1,data_column,0)) -> 55.1 | E31: =INDEX(data,MATCH($A31,data_row,0),MATCH(E$1,data_column,0)) -> -4.3 | F31: =INDEX(data,MATCH($A31,data_row,0),MATCH(F$1,data_column,0)) -> 0 | G31: =INDEX(data,MATCH($A31,data_row,0),MATCH(G$1,data_column,0)) -> 0 | H31: =INDEX(data,MATCH($A31,data_row,0),MATCH(H$1,data_column,0)) -> 0 | I31: =INDEX(data,MATCH($A31,data_row,0),MATCH(I$1,data_column,0)) -> 0 | J31: =INDEX(data,MATCH($A31,data_row,0),MATCH(J$1,data_column,0)) -> 0 | K31: =INDEX(data,MATCH($A31,data_row,0),MATCH(K$1,data_column,0)) -> 0
A32: Cash flow from financing activities | B32: INR Mn | C32: =INDEX(data,MATCH($A32,data_row,0),MATCH(C$1,data_column,0)) -> -3710.6 | D32: =INDEX(data,MATCH($A32,data_row,0),MATCH(D$1,data_column,0)) -> 406.6 | E32: =INDEX(data,MATCH($A32,data_row,0),MATCH(E$1,data_column,0)) -> -7897.5 | F32: =INDEX(data,MATCH($A32,data_row,0),MATCH(F$1,data_column,0)) -> -3046.8 | G32: =INDEX(data,MATCH($A32,data_row,0),MATCH(G$1,data_column,0)) -> -3112.5078 | H32: =INDEX(data,MATCH($A32,data_row,0),MATCH(H$1,data_column,0)) -> -3485.6956 | I32: =INDEX(data,MATCH($A32,data_row,0),MATCH(I$1,data_column,0)) -> -3787.9457 | J32: =INDEX(data,MATCH($A32,data_row,0),MATCH(J$1,data_column,0)) -> -4041.6222 | K32: =INDEX(data,MATCH($A32,data_row,0),MATCH(K$1,data_column,0)) -> -4316.8267
A34: Key Ratios/ Growth rate
A36: Revenue- y-o-y growth | B36: % | C36: na | D36: =IFERROR(D6/C6-1,"na") -> 0.046064308 | E36: =IFERROR(E6/D6-1,"na") -> 0.083715076 | F36: =IFERROR(F6/E6-1,"na") -> 0.18512464 | G36: =IFERROR(G6/F6-1,"na") -> 0.069442112 | H36: =IFERROR(H6/G6-1,"na") -> 0.093550455 | I36: =IFERROR(I6/H6-1,"na") -> 0.06945365 | J36: =IFERROR(J6/I6-1,"na") -> 0.069636378 | K36: =IFERROR(K6/J6-1,"na") -> 0.069817602
A37: Gross margin | B37: % | C37: =IFERROR(C7/C$6,"na") -> 0.51833056 | D37: =IFERROR(D7/D$6,"na") -> 0.53005898 | E37: =IFERROR(E7/E$6,"na") -> 0.52560375 | F37: =IFERROR(F7/F$6,"na") -> 0.49273137 | G37: =IFERROR(G7/G$6,"na") -> 0.51 | H37: =IFERROR(H7/H$6,"na") -> 0.51 | I37: =IFERROR(I7/I$6,"na") -> 0.52 | J37: =IFERROR(J7/J$6,"na") -> 0.52 | K37: =IFERROR(K7/K$6,"na") -> 0.52
A38: EBITDA margin | B38: % | C38: =IFERROR(C8/C$6,"na") -> 0.21952155 | D38: =IFERROR(D8/D$6,"na") -> 0.22532443 | E38: =IFERROR(E8/E$6,"na") -> 0.22034171 | F38: =IFERROR(F8/F$6,"na") -> 0.1985621 | G38: =IFERROR(G8/G$6,"na") -> 0.20013138 | H38: =IFERROR(H8/H$6,"na") -> 0.19936819 | I38: =IFERROR(I8/I$6,"na") -> 0.19932611 | J38: =IFERROR(J8/J$6,"na") -> 0.19932887 | K38: =IFERROR(K8/K$6,"na") -> 0.19933409
A39: EBIT margin | B39: % | C39: =IFERROR(C9/C$6,"na") -> 0.19472758 | D39: =IFERROR(D9/D$6,"na") -> 0.20482518 | E39: =IFERROR(E9/E$6,"na") -> 0.20064728 | F39: =IFERROR(F9/F$6,"na") -> 0.18106953 | G39: =IFERROR(G9/G$6,"na") -> 0.18327507 | H39: =IFERROR(H9/H$6,"na") -> 0.18309942 | I39: =IFERROR(I9/I$6,"na") -> 0.18339259 | J39: =IFERROR(J9/J$6,"na") -> 0.18381933 | K39: =IFERROR(K9/K$6,"na") -> 0.18422817
A40: PAT margin | B40: % | C40: =IFERROR(C10/C$6,"na") -> 0.14071274 | D40: =IFERROR(D10/D$6,"na") -> 0.15311058 | E40: =IFERROR(E10/E$6,"na") -> 0.15809923 | F40: =IFERROR(F10/F$6,"na") -> 0.12877578 | G40: =IFERROR(G10/G$6,"na") -> 0.13487145 | H40: =IFERROR(H10/H$6,"na") -> 0.13402799 | I40: =IFERROR(I10/I$6,"na") -> 0.13371665 | J40: =IFERROR(J10/J$6,"na") -> 0.13352366 | K40: =IFERROR(K10/K$6,"na") -> 0.13334766
A41: Adjusted PAT margin | B41: % | C41: =IFERROR(C11/C$6,"na") -> 0.14160854 | D41: =IFERROR(D11/D$6,"na") -> 0.15414498 | E41: =IFERROR(E11/E$6,"na") -> 0.15809923 | F41: =IFERROR(F11/F$6,"na") -> 0.12877578 | G41: =IFERROR(G11/G$6,"na") -> 0.13487145 | H41: =IFERROR(H11/H$6,"na") -> 0.13402799 | I41: =IFERROR(I11/I$6,"na") -> 0.13371665 | J41: =IFERROR(J11/J$6,"na") -> 0.13352366 | K41: =IFERROR(K11/K$6,"na") -> 0.13334766
A43: Debt/Equity | B43: x | C43: =(C19+C20)/(Financials!G123+Financials!G124) -> 0.030284846 | D43: =(D19+D20)/(Financials!L123+Financials!L124) -> 0.028093497 | E43: =(E19+E20)/(Financials!Q123+Financials!Q124) -> 0.034288928 | F43: =(F19+F20)/(Financials!V123+Financials!V124) -> 0.029190181 | G43: =(G19+G20)/(Financials!AA123+Financials!AA124) -> 0.024870195 | H43: =(H19+H20)/(Financials!AF123+Financials!AF124) -> 0.021463303 | I43: =(I19+I20)/(Financials!AK123+Financials!AK124) -> 0.018745969 | J43: =(J19+J20)/(Financials!AP123+Financials!AP124) -> 0.01651206 | K43: =(K19+K20)/(Financials!AU123+Financials!AU124) -> 0.014646966
A44: Share Price | B44: INR/share | C44: 565.2 | D44: 671.4 | E44: 825.5 | F44: 1086 | G44: =rCP -> 1104 | H44: =rCP -> 1104 | I44: =rCP -> 1104 | J44: =rCP -> 1104 | K44: =rCP -> 1104
A45: Total shares outstanding | B45: Shares | C45: =INDEX(data,MATCH($A45,data_row,0),MATCH(C$1,data_column,0)) -> 512.7 | D45: =INDEX(data,MATCH($A45,data_row,0),MATCH(D$1,data_column,0)) -> 512.7 | E45: =INDEX(data,MATCH($A45,data_row,0),MATCH(E$1,data_column,0)) -> 507.8 | F45: =INDEX(data,MATCH($A45,data_row,0),MATCH(F$1,data_column,0)) -> 508 | G45: =INDEX(data,MATCH($A45,data_row,0),MATCH(G$1,data_column,0)) -> 508 | H45: =INDEX(data,MATCH($A45,data_row,0),MATCH(H$1,data_column,0)) -> 508 | I45: =INDEX(data,MATCH($A45,data_row,0),MATCH(I$1,data_column,0)) -> 508 | J45: =INDEX(data,MATCH($A45,data_row,0),MATCH(J$1,data_column,0)) -> 508 | K45: =INDEX(data,MATCH($A45,data_row,0),MATCH(K$1,data_column,0)) -> 508
A46: Market Captalization | B46: INR Mn | C46: =C44*C45 -> 289778.04 | D46: =D44*D45 -> 344226.78 | E46: =E44*E45 -> 419188.9 | F46: =F44*F45 -> 551688 | G46: =G44*G45 -> 560832 | H46: =H44*H45 -> 560832 | I46: =I44*I45 -> 560832 | J46: =J44*J45 -> 560832 | K46: =K44*K45 -> 560832
A47: Net Debt | B47: INR Mn | C47: =Financials!G100+Financials!G113-Financials!G65 -> -476.6 | D47: =Financials!L100+Financials!L113-Financials!L65 -> -24.3 | E47: =Financials!Q100+Financials!Q113-Financials!Q65 -> -410.3 | F47: =Financials!V100+Financials!V113-Financials!V65 -> -6188.2113 | G47: =Financials!AA100+Financials!AA113-Financials!AA65 -> -11888.022 | H47: =Financials!AF100+Financials!AF113-Financials!AF65 -> -17710.007 | I47: =Financials!AK100+Financials!AK113-Financials!AK65 -> -24986.363 | J47: =Financials!AP100+Financials!AP113-Financials!AP65 -> -32199.017 | K47: =Financials!AU100+Financials!AU113-Financials!AU65 -> -40162.539
A48: Minority Interest | B48: INR Mn | C48: =INDEX(data,MATCH($A48,data_row,0),MATCH(C$1,data_column,0)) -> 427.3 | D48: =INDEX(data,MATCH($A48,data_row,0),MATCH(D$1,data_column,0)) -> 1273.2 | E48: =INDEX(data,MATCH($A48,data_row,0),MATCH(E$1,data_column,0)) -> 1750.1 | F48: =INDEX(data,MATCH($A48,data_row,0),MATCH(F$1,data_column,0)) -> 1776.74 | G48: =INDEX(data,MATCH($A48,data_row,0),MATCH(G$1,data_column,0)) -> 1818.5274 | H48: =INDEX(data,MATCH($A48,data_row,0),MATCH(H$1,data_column,0)) -> 1863.9383 | I48: =INDEX(data,MATCH($A48,data_row,0),MATCH(I$1,data_column,0)) -> 1912.3902 | J48: =INDEX(data,MATCH($A48,data_row,0),MATCH(J$1,data_column,0)) -> 1964.1414 | K48: =INDEX(data,MATCH($A48,data_row,0),MATCH(K$1,data_column,0)) -> 2019.4328
A49: Investment | B49: INR Mn | C49: =Financials!G68+Financials!G86 -> 7467.9 | D49: =Financials!L68+Financials!L86 -> 14858.3 | E49: =Financials!Q68+Financials!Q86 -> 12656.3 | F49: =Financials!V68+Financials!V86 -> 12656.3 | G49: =Financials!AA68+Financials!AA86 -> 12656.3 | H49: =Financials!AF68+Financials!AF86 -> 12656.3 | I49: =Financials!AK68+Financials!AK86 -> 12656.3 | J49: =Financials!AP68+Financials!AP86 -> 12656.3 | K49: =Financials!AU68+Financials!AU86 -> 12656.3
...

Sheet Financials
A1: Financials | C1: 1Q2016 | D1: 2Q2016 | E1: 3Q2016 | F1: 4Q2016 | G1: FY2016 | H1: 1Q2017 | I1: 2Q2017 | J1: 3Q2017 | K1: 4Q2017 | L1: FY2017 | M1: 1Q2018 | N1: 2Q2018 | O1: 3Q2018 | P1: 4Q2018 | Q1: FY2018 | R1: 1Q2019 | S1: 2Q2019 | T1: 3Q2019 | U1: 4Q2019 | V1: FY2019 | W1: 1Q2020 | X1: 2Q2020 | Y1: 3Q2020 | Z1: 4Q2020 | AA1: FY2020 | AB1: 1Q2021 | AC1: 2Q2021 | AD1: 3Q2021 | AE1: 4Q2021 | AF1: FY2021 | AG1: 1Q2022 | AH1: 2Q2022 | AI1: 3Q2022 | AJ1: 4Q2022 | AK1: FY2022 | AL1: 1Q2023 | AM1: 2Q2023 | AN1: 3Q2023 | AO1: 4Q2023 | AP1: FY2023 | AQ1: 1Q2024 | AR1: 2Q2024 | AS1: 3Q2024 | AT1: 4Q2024 | AU1: FY2024
C2: 42185 | D2: 42277 | E2: 42369 | F2: 42460 | G2: 42460 | H2: 42551 | I2: 42643 | J2: 42735 | K2: 42825 | L2: 42825 | M2: 42916 | N2: 43008 | O2: 43100 | P2: 43190 | Q2: 43190 | R2: 43281 | S2: 43373 | T2: 43465 | U2: 43555 | V2: 43555 | W2: 43646 | X2: 43738 | Y2: 43830 | Z2: 43921 | AA2: 43921 | AB2: 44012 | AC2: 44104 | AD2: 44196 | AE2: 44286 | AF2: 44286 | AG2: 44377 | AH2: 44469 | AI2: 44561 | AJ2: 44651 | AK2: 44651 | AL2: 44742 | AM2: 44834 | AN2: 44926 | AO2: 45016 | AP2: 45016 | AQ2: 45107 | AR2: 45199 | AS2: 45291 | AT2: 45382 | AU2: 45382
C3: A | D3: A | E3: A | F3: A | G3: A | H3: A | I3: A | J3: A | K3: A | L3: A | M3: A | N3: A | O3: A | P3: A | Q3: A | R3: A | S3: A | T3: A | U3: F | V3: F | W3: F | X3: F | Y3: F | Z3: F | AA3: F | AB3: F | AC3: F | AD3: F | AE3: F | AF3: F | AG3: F | AH3: F | AI3: F | AJ3: F | AK3: F | AL3: F | AM3: F | AN3: F | AO3: F | AP3: F | AQ3: F | AR3: F | AS3: F | AT3: F | AU3: F
A5: No. of days | C5: 91 | D5: =D2-C2 -> 92 | E5: =E2-D2 -> 92 | F5: =F2-E2 -> 91 | G5: =SUM(C5:F5) -> 366 | H5: =H2-F2 -> 91 | I5: =I2-H2 -> 92 | J5: =J2-I2 -> 92 | K5: =K2-J2 -> 90 | L5: =SUM(H5:K5) -> 365 | M5: =M2-K2 -> 91 | N5: =N2-M2 -> 92 | O5: =O2-N2 -> 92 | P5: =P2-O2 -> 90 | Q5: =SUM(M5:P5) -> 365 | R5: =R2-P2 -> 91 | S5: =S2-R2 -> 92 | T5: =T2-S2 -> 92 | U5: =U2-T2 -> 90 | V5: =SUM(R5:U5) -> 365 | W5: =W2-U2 -> 91 | X5: =X2-W2 -> 92 | Y5: =Y2-X2 -> 92 | Z5: =Z2-Y2 -> 91 | AA5: =SUM(W5:Z5) -> 366 | AB5: =AB2-Z2 -> 91 | AC5: =AC2-AB2 -> 92 | AD5: =AD2-AC2 -> 92 | AE5: =AE2-AD2 -> 90 | AF5: =SUM(AB5:AE5) -> 365 | AG5: =AG2-AE2 -> 91 | AH5: =AH2-AG2 -> 92 | AI5: =AI2-AH2 -> 92 | AJ5: =AJ2-AI2 -> 90 | AK5: =SUM(AG5:AJ5) -> 365 | AL5: =AL2-AJ2 -> 91 | AM5: =AM2-AL2 -> 92 | AN5: =AN2-AM2 -> 92 | AO5: =AO2-AN2 -> 90 | AP5: =SUM(AL5:AO5) -> 365 | AQ5: =AQ2-AO2 -> 91 | AR5: =AR2-AQ2 -> 92 | AS5: =AS2-AR2 -> 92 | AT5: =AT2-AS2 -> 91 | AU5: =SUM(AQ5:AT5) -> 366
A7: Income Statement
A9: Revenue | B9: INR Mn | C9: =C11+C12+C13 -> 14694.6 | D9: =D11+D12+D13 -> 13200.6 | E9: =E11+E12+E13 -> 13390.8 | F9: =F11+F12+F13 -> 12408.5 | G9: =G11+G12+G13 -> 53694.5 | H9: =H11+H12+H13 -> 15693.7 | I9: =I11+I12+I13 -> 14176.8 | J9: =J11+J12+J13 -> 13343.5 | ... T9: =T11+T12+T13 -> 18483 | U9: ='Operational Drivers'!U6 -> 17740.437 | V9: =R9+S9+T9+U9 -> 72138.537 | W9: ='Operational Drivers'!W6 -> 19611.711 | X9: ='Operational Drivers'!X6 -> 18792.306 | Y9: ='Operational Drivers'!Y6 -> 19763.872 | Z9: ='Operational Drivers'!Z6 -> 18980.101 | AA9: =W9+X9+Y9+Z9 -> 77147.989 | AB9: ='Operational Drivers'!AB6 -> 21442.956 | AC9: ='Operational Drivers'!AC6 -> 20547.039 | AD9: ='Operational Drivers'!AD6 -> 21609.326 | AE9: ='Operational Drivers'!AE6 -> 20765.898 | AF9: =AB9+AC9+AD9+AE9 -> 84365.219 | AG9: ='Operational Drivers'!AG6 -> 22930.754 | AH9: ='Operational Drivers'!AH6 -> 21972.675 | AI9: ='Operational Drivers'!AI6 -> 23108.667 | AJ9: ='Operational Drivers'!AJ6 -> 22212.595 | AK9: =AG9+AH9+AI9+AJ9 -> 90224.691 | AL9: ='Operational Drivers'!AL6 -> 24525.984 | AM9: ='Operational Drivers'!AM6 -> 23501.254 | AN9: ='Operational Drivers'!AN6 -> 24716.274 | AO9: ='Operational Drivers'!AO6 -> 23764.1 | AP9: =AL9+AM9+AN9+AO9 -> 96507.612 | AQ9: ='Operational Drivers'!AQ6 -> 26236.648 | AR9: ='Operational Drivers'!AR6 -> 25140.444 | AS9: ='Operational Drivers'!AS6 -> 26440.21 | AT9: ='Operational Drivers'!AT6 -> 25428.239 | AU9: =AQ9+AR9+AS9+AT9 -> 103245.54
A10: y-o-y growth | B10: % | C10: na | D10: na | E10: na | F10: na | G10: na | H10: =IFERROR(H9/C9-1,"na") -> 0.067990963 | I10: =IFERROR(I9/D9-1,"na") -> 0.073951184 | J10: =IFERROR(J9/E9-1,"na") -> -0.0035322759 | K10: =IFERROR(K9/F9-1,"na") -> 0.043953741 | L10: =IFERROR(L9/G9-1,"na") -> 0.046064308 | M10: =IFERROR(M9/H9-1,"na") -> -0.025774674 | N10: =IFERROR(N9/I9-1,"na") -> 0.079136335 | O10: =IFERROR(O9/J9-1,"na") -> 0.15629333 | ... AU10: =IFERROR(AU9/AP9-1,"na") -> 0.069817602
A11: Revenue from operations | B11: INR Mn | C11: 14621.5 | D11: 13134.4 | E11: 13323.2 | F11: 12334.7 | G11: =C11+D11+E11+F11 -> 53413.8 | H11: 16838.2 | I11: 15220.4 | J11: 14308.8 | K11: 14043.2 | L11: =H11+I11+J11+K11 -> 60410.6 | M11: 16692.7 | N11: 15298.7 | O11: 15429 | P11: 14853.1 | Q11: =M11+N11+O11+P11 -> 62273.5 | R11: 18340.7 | S11: 17574.4 | T11: 18483
A12: Excise duty | B12: INR Mn | C12: 0 | D12: 0 | E12: 0 | F12: 0 | G12: =C12+D12+E12+F12 -> 0 | H12: -1219.4 | I12: -1118.3 | J12: -1028.2 | K12: -1089.3 | L12: =H12+I12+J12+K12 -> -4455.2 | M12: -1403.5 | N12: 0 | O12: 0 | P12: 0 | Q12: =M12+N12+O12+P12 -> -1403.5 | R12: 0 | S12: 0 | T12: 0
A13: Other operating income | B13: INR Mn | C13: 73.1 | D13: 66.2 | E13: 67.6 | F13: 73.8 | G13: =C13+D13+E13+F13 -> 280.7 | H13: 74.9 | I13: 74.7 | J13: 62.9 | K13: 0 | L13: =H13+I13+J13+K13 -> 212.5 | Q13: =M13+N13+O13+P13 -> 0
A14: Cost of Goods Sold | B14: INR Mn | C14: =C16+C17+C18 -> -7486.4 | D14: =D16+D17+D18 -> -6354.5 | E14: =E16+E17+E18 -> -6474.5 | F14: =F16+F17+F18 -> -5547.6 | G14: =G16+G17+G18 -> -25863 | H14: =H16+H17+H18 -> -7479.1 | I14: =I16+I17+I18 -> -6597.9 | J14: =J16+J17+J18 -> -6245.8 | ... T14: =T16+T17+T18 -> -9752 | U14: =-IFERROR(U9*U15,"na") -> -8876.2167 | V14: =R14+S14+T14+U14 -> -36593.617 | W14: =-IFERROR(W9*W15,"na") -> -9609.7381 | X14: =-IFERROR(X9*X15,"na") -> -9208.2299 | Y14: =-IFERROR(Y9*Y15,"na") -> -9684.2972 | Z14: =-IFERROR(Z9*Z15,"na") -> -9300.2496 | AA14: =W14+X14+Y14+Z14 -> -37802.515 | AB14: =-IFERROR(AB9*AB15,"na") -> -10507.048 | AC14: =-IFERROR(AC9*AC15,"na") -> -10068.049 | AD14: =-IFERROR(AD9*AD15,"na") -> -10588.57 | AE14: =-IFERROR(AE9*AE15,"na") -> -10175.29 | AF14: =AB14+AC14+AD14+AE14 -> -41338.957 | AG14: =-IFERROR(AG9*AG15,"na") -> -11006.762 | AH14: =-IFERROR(AH9*AH15,"na") -> -10546.884 | AI14: =-IFERROR(AI9*AI15,"na") -> -11092.16 | AJ14: =-IFERROR(AJ9*AJ15,"na") -> -10662.046 | AK14: =AG14+AH14+AI14+AJ14 -> -43307.852 | AL14: =-IFERROR(AL9*AL15,"na") -> -11772.472 | AM14: =-IFERROR(AM9*AM15,"na") -> -11280.602 | AN14: =-IFERROR(AN9*AN15,"na") -> -11863.811 | AO14: =-IFERROR(AO9*AO15,"na") -> -11406.768 | AP14: =AL14+AM14+AN14+AO14 -> -46323.654 | AQ14: =-IFERROR(AQ9*AQ15,"na") -> -12593.591 | AR14: =-IFERROR(AR9*AR15,"na") -> -12067.413 | AS14: =-IFERROR(AS9*AS15,"na") -> -12691.301 | AT14: =-IFERROR(AT9*AT15,"na") -> -12205.555 | AU14: =AQ14+AR14+AS14+AT14 -> -49557.86
A15: as a % of sales | B15: % | C15: =IFERROR(-C14/C9,"na") -> 0.50946606 | D15: =IFERROR(-D14/D9,"na") -> 0.48137963 | E15: =IFERROR(-E14/E9,"na") -> 0.4835036 | F15: =IFERROR(-F14/F9,"na") -> 0.44708063 | G15: =IFERROR(-G14/G9,"na") -> 0.48166944 | H15: =IFERROR(-H14/H9,"na") -> 0.47656703 | I15: =IFERROR(-I14/I9,"na") -> 0.46540122 | J15: =IFERROR(-J14/J9,"na") -> 0.46807809 | ... T15: =IFERROR(-T14/T9,"na") -> 0.52761998 | U15: =MEDIAN(P15,R15:T15) -> 0.50033811 | V15: =IFERROR(-V14/V9,"na") -> 0.50726863 | W15: 0.49 | X15: =W15 -> 0.49 | Y15: =X15 -> 0.49 | Z15: =Y15 -> 0.49 | AA15: =IFERROR(-AA14/AA9,"na") -> 0.49 | AB15: =MEDIAN(W15:Z15) -> 0.49 | AC15: =MEDIAN(X15:Z15,AB15) -> 0.49 | AD15: =MEDIAN(Y15:Z15,AB15:AC15) -> 0.49 | AE15: =MEDIAN(Z15,AB15:AD15) -> 0.49 | AF15: =IFERROR(-AF14/AF9,"na") -> 0.49 | AG15: 0.48 | AH15: =AG15 -> 0.48 | AI15: =AH15 -> 0.48 | AJ15: =AI15 -> 0.48 | AK15: =IFERROR(-AK14/AK9,"na") -> 0.48 | AL15: =MEDIAN(AG15:AJ15) -> 0.48 | AM15: =MEDIAN(AH15:AJ15,AL15) -> 0.48 | AN15: =MEDIAN(AI15:AJ15,AL15:AM15) -> 0.48 | AO15: =MEDIAN(AJ15,AL15:AN15) -> 0.48 | AP15: =IFERROR(-AP14/AP9,"na") -> 0.48 | AQ15: =MEDIAN(AL15:AO15) -> 0.48 | AR15: =MEDIAN(AM15:AO15,AQ15) -> 0.48 | AS15: =MEDIAN(AN15:AO15,AQ15:AR15) -> 0.48 | AT15: =MEDIAN(AO15,AQ15:AS15) -> 0.48 | AU15: =IFERROR(-AU14/AU9,"na") -> 0.48
A16: Cost of materials consumed | B16: INR Mn | C16: -6111.3 | D16: -6016.7 | E16: -5513.6 | F16: -5344.6 | G16: =C16+D16+E16+F16 -> -22986.2 | H16: -5853.4 | I16: -5485.6 | J16: -5231.4 | K16: -6133.9 | L16: =H16+I16+J16+K16 -> -22704.3 | M16: -6455.4 | N16: -5519.1 | O16: -6702.8 | P16: -6972.9 | Q16: =M16+N16+O16+P16 -> -25650.2 | R16: -7917.7 | S16: -8083.4 | T16: -8705.2
A17: Purchases of stock-in-trade | B17: INR Mn | C17: -584.1 | D17: -639 | E17: -658.8 | F17: -778 | G17: =C17+D17+E17+F17 -> -2659.9 | H17: -1046.6 | I17: -1082.8 | J17: -992.7 | K17: -876.5 | L17: =H17+I17+J17+K17 -> -3998.6 | M17: -862.4 | N17: -865.4 | O17: -629.3 | P17: -831.5 | Q17: =M17+N17+O17+P17 -> -3188.6 | R17: -1054.6 | S17: -991.3 | T17: -1147.6
A18: Change in inventories of FG, WIP, and SIT | B18: INR Mn | C18: -791 | D18: 301.2 | E18: -302.1 | F18: 575 | G18: =C18+D18+E18+F18 -> -216.9 | H18: -579.1 | I18: -29.5 | J18: -21.7 | K18: 937.6 | L18: =H18+I18+J18+K18 -> 307.3 | M18: -63.3 | N18: -805.3 | O18: 145.7 | P18: 685.2 | Q18: =M18+N18+O18+P18 -> -37.7 | R18: -101.5 | S18: 183.1 | T18: 100.8
A19: Gross Profit | B19: INR Mn | C19: =C9+C14 -> 7208.2 | D19: =D9+D14 -> 6846.1 | E19: =E9+E14 -> 6916.3 | F19: =F9+F14 -> 6860.9 | G19: =G9+G14 -> 27831.5 | H19: =H9+H14 -> 8214.6 | I19: =I9+I14 -> 7578.9 | J19: =J9+J14 -> 7097.7 | ... AU19: =AU9+AU14 -> 53687.682
A20: gross margin | B20: % | C20: =IFERROR(C19/C9,"na") -> 0.49053394 | D20: =IFERROR(D19/D9,"na") -> 0.51862037 | E20: =IFERROR(E19/E9,"na") -> 0.5164964 | F20: =IFERROR(F19/F9,"na") -> 0.55291937 | G20: =IFERROR(G19/G9,"na") -> 0.51833056 | H20: =IFERROR(H19/H9,"na") -> 0.52343297 | I20: =IFERROR(I19/I9,"na") -> 0.53459878 | J20: =IFERROR(J19/J9,"na") -> 0.53192191 | ... AU20: =IFERROR(AU19/AU9,"na") -> 0.52
A21: Selling, General & Administration | B21: INR Mn | C21: -1423 | D21: -1393.3 | E21: -1441.7 | F21: -1485.4 | G21: =C21+D21+E21+F21 -> -5743.4 | H21: -1625.2 | I21: -1562.4 | J21: -1652.6 | K21: -1612.5 | L21: =H21+I21+J21+K21 -> -6452.7 | M21: -1809.2 | N21: -1837 | O21: -1743.3 | P21: -1734.5 | Q21: =M21+N21+O21+P21 -> -7124 | R21: -2071 | S21: -2037 | T21: -2087.4 | U21: =IFERROR((P21*(1+U22)),"na") -> -1954.4155 | V21: =R21+S21+T21+U21 -> -8149.8155 | W21: =IFERROR((R21*(1+W22)),"na") -> -2352.1319 | X21: =IFERROR((S21*(1+X22)),"na") -> -2304.3928 | Y21: =IFERROR((T21*(1+Y22)),"na") -> -2366.0834 | Z21: =IFERROR((U21*(1+Z22)),"na") -> -2213.1561 | AA21: =W21+X21+Y21+Z21 -> -9235.7643 | AB21: =IFERROR((W21*(1+AB22)),"na") -> -2664.8421 | AC21: =IFERROR((X21*(1+AC22)),"na") -> -2610.1112 | AD21: =IFERROR((Y21*(1+AD22)),"na") -> -2680.3173 | AE21: =IFERROR((Z21*(1+AE22)),"na") -> -2506.9252 | AF21: =AB21+AC21+AD21+AE21 -> -10462.196 | AG21: =IFERROR((AB21*(1+AG22)),"na") -> -3018.6601 | AH21: =IFERROR((AC21*(1+AH22)),"na") -> -2956.6168 | AI21: =IFERROR((AD21*(1+AI22)),"na") -> -3036.1666 | AJ21: =IFERROR((AE21*(1+AJ22)),"na") -> -2839.7433 | AK21: =AG21+AH21+AI21+AJ21 -> -11851.187 | AL21: =IFERROR((AG21*(1+AL22)),"na") -> -3419.4225 | AM21: =IFERROR((AH21*(1+AM22)),"na") -> -3349.139 | AN21: =IFERROR((AI21*(1+AN22)),"na") -> -3439.2515 | AO21: =IFERROR((AJ21*(1+AO22)),"na") -> -3216.75 | AP21: =AL21+AM21+AN21+AO21 -> -13424.563 | AQ21: =IFERROR((AL21*(1+AQ22)),"na") -> -3873.3885 | AR21: =IFERROR((AM21*(1+AR22)),"na") -> -3793.7738 | AS21: =IFERROR((AN21*(1+AS22)),"na") -> -3895.8498 | AT21: =IFERROR((AO21*(1+AT22)),"na") -> -3643.8088 | AU21: =AQ21+AR21+AS21+AT21 -> -15206.821
A22: y-o-y growth | B22: % | C22: na | D22: na | E22: na | F22: na | G22: na | H22: =IFERROR(H21/C21-1,"na") -> 0.14209417 | I22: =IFERROR(I21/D21-1,"na") -> 0.12136654 | J22: =IFERROR(J21/E21-1,"na") -> 0.14628564 | K22: =IFERROR(K21/F21-1,"na") -> 0.085566177 | L22: =IFERROR(L21/G21-1,"na") -> 0.12349828 | M22: =IFERROR(M21/H21-1,"na") -> 0.11321683 | N22: =IFERROR(N21/I21-1,"na") -> 0.17575525 | O22: =IFERROR(O21/J21-1,"na") -> 0.054883214 | ... T22: =IFERROR(T21/O21-1,"na") -> 0.19738427 | U22: =MEDIAN(P22,R22:T22) -> 0.126789 | V22: =IFERROR(V21/Q21-1,"na") -> 0.14399432 | W22: =MEDIAN(R22:U22) -> 0.13574692 | X22: =MEDIAN(S22:U22,W22) -> 0.13126796 | Y22: =MEDIAN(T22:U22,W22:X22) -> 0.13350744 | Z22: =MEDIAN(U22,W22:Y22) -> 0.1323877 | AA22: =IFERROR(AA21/V21-1,"na") -> 0.13324826 | AB22: =MEDIAN(W22:Z22) -> 0.13294757 | AC22: =MEDIAN(X22:Z22,AB22) -> 0.13266764 | AD22: =MEDIAN(Y22:Z22,AB22:AC22) -> 0.1328076 | AE22: =MEDIAN(Z22,AB22:AD22) -> 0.13273762 | AF22: =IFERROR(AF21/AA21-1,"na") -> 0.13279156 | AG22: =MEDIAN(AB22:AE22) -> 0.13277261 | AH22: =MEDIAN(AC22:AE22,AG22) -> 0.13275512 | AI22: =MEDIAN(AD22:AE22,AG22:AH22) -> 0.13276386 | AJ22: =MEDIAN(AE22,AG22:AI22) -> 0.13275949 | AK22: =IFERROR(AK21/AF21-1,"na") -> 0.13276286 | AL22: =MEDIAN(AG22:AJ22) -> 0.13276168 | AM22: =MEDIAN(AH22:AJ22,AL22) -> 0.13276058 | AN22: =MEDIAN(AI22:AJ22,AL22:AM22) -> 0.13276113 | AO22: =MEDIAN(AJ22,AL22:AN22) -> 0.13276086 | AP22: =IFERROR(AP21/AK21-1,"na") -> 0.13276107 | AQ22: =MEDIAN(AL22:AO22) -> 0.13276099 | AR22: =MEDIAN(AM22:AO22,AQ22) -> 0.13276093 | AS22: =MEDIAN(AN22:AO22,AQ22:AR22) -> 0.13276096 | AT22: =MEDIAN(AO22,AQ22:AS22) -> 0.13276094 | AU22: =IFERROR(AU21/AP21-1,"na") -> 0.13276096
A23: Other operating expense | B23: INR Mn | C23: -2348.3 | D23: -2438.9 | E23: -2522 | F23: -2991.8 | G23: =C23+D23+E23+F23 -> -10301 | H23: -2646.1 | I23: -2791.1 | J23: -2536.3 | K23: -2690.1 | L23: =H23+I23+J23+K23 -> -10663.6 | M23: -2889.1 | N23: -2511.3 | O23: -2796.8 | P23: -3260.1 | Q23: =M23+N23+O23+P23 -> -11457.3 | R23: -3379.3 | S23: -2997.4 | T23: -3276.1 | U23: =U24-U19-U21 -> -3418.3253 | V23: =R23+S23+T23+U23 -> -13071.125 | W23: =W24-W19-W21 -> -3667.7974 | X23: =X24-X19-X21 -> -3522.5833 | Y23: =Y24-Y19-Y21 -> -3792.7991 | Z23: =Z24-Z19-Z21 -> -3686.7973 | AA23: =W23+X23+Y23+Z23 -> -14669.977 | AB23: =AB24-AB19-AB21 -> -3992.0872 | AC23: =AC24-AC19-AC21 -> -3772.7624 | AD23: =AD24-AD19-AD21 -> -4034.5504 | AE23: =AE24-AE19-AE21 -> -3944.9246 | AF23: =AB23+AC23+AD23+AE23 -> -15744.325 | AG23: =AG24-AG19-AG21 -> -4334.34 | AH23: =AH24-AH19-AH21 -> -4089.5154 | AI23: =AI24-AI19-AI21 -> -4374.2891 | AJ23: =AJ24-AJ19-AJ21 -> -4283.3715 | AK23: =AG23+AH23+AI23+AJ23 -> -17081.516 | AL23: =AL24-AL19-AL21 -> -4445.302 | AM23: =AM24-AM19-AM21 -> -4187.0878 | AN23: =AN24-AN19-AN21 -> -4486.5057 | AO23: =AO24-AO19-AO21 -> -4403.7467 | AP23: =AL23+AM23+AN23+AO23 -> -17522.642 | AQ23: =AQ24-AQ19-AQ21 -> -4539.7761 | AR23: =AR24-AR19-AR21 -> -4267.9618 | AS23: =AS24-AS19-AS21 -> -4582.5763 | AT23: =AT24-AT19-AT21 -> -4510.1908 | AU23: =AQ23+AR23+AS23+AT23 -> -17900.505
A24: EBITDA | B24: INR Mn | C24: =C19+C21+C23 -> 3436.9 | D24: =D19+D21+D23 -> 3013.9 | E24: =E19+E21+E23 -> 2952.6 | F24: =F19+F21+F23 -> 2383.7 | G24: =G19+G21+G23 -> 11787.1 | H24: =H19+H21+H23 -> 3943.3 | I24: =I19+I21+I23 -> 3225.4 | J24: =J19+J21+J23 -> 2908.8 | ... T24: =T19+T21+T23 -> 3367.5 | U24: ='Operational Drivers'!U43 -> 3491.4796 | V24: =R24+S24+T24+U24 -> 14323.98 | W24: ='Operational Drivers'!W43 -> 3982.0431 | X24: ='Operational Drivers'!X43 -> 3757.0999 | Y24: ='Operational Drivers'!Y43 -> 3920.6921 | Z24: ='Operational Drivers'!Z43 -> 3779.8981 | AA24: =W24+X24+Y24+Z24 -> 15439.733 | AB24: ='Operational Drivers'!AB43 -> 4278.9783 | AC24: ='Operational Drivers'!AC43 -> 4096.1165 | AD24: ='Operational Drivers'!AD43 -> 4305.8883 | AE24: ='Operational Drivers'!AE43 -> 4138.7581 | AF24: =AB24+AC24+AD24+AE24 -> 16819.741 | AG24: ='Operational Drivers'!AG43 -> 4570.9919 | AH24: ='Operational Drivers'!AH43 -> 4379.6588 | AI24: ='Operational Drivers'!AI43 -> 4606.051 | AJ24: ='Operational Drivers'!AJ43 -> 4427.4348 | AK24: =AG24+AH24+AI24+AJ24 -> 17984.137 | AL24: ='Operational Drivers'!AL43 -> 4888.7871 | AM24: ='Operational Drivers'!AM43 -> 4684.4253 | AN24: ='Operational Drivers'!AN43 -> 4926.7051 | AO24: ='Operational Drivers'!AO43 -> 4736.8354 | AP24: =AL24+AM24+AN24+AO24 -> 19236.753 | AQ24: ='Operational Drivers'!AQ43 -> 5229.8924 | AR24: ='Operational Drivers'!AR43 -> 5011.2955 | AS24: ='Operational Drivers'!AS43 -> 5270.4832 | AT24: ='Operational Drivers'!AT43 -> 5068.6848 | AU24: =AQ24+AR24+AS24+AT24 -> 20580.356
A25: y-o-y growth | B25: % | C25: na | D25: na | E25: na | F25: na | G25: na | H25: =IFERROR(H24/C24-1,"na") -> 0.14734208 | I25: =IFERROR(I24/D24-1,"na") -> 0.070174856 | J25: =IFERROR(J24/E24-1,"na") -> -0.014834383 | K25: =IFERROR(K24/F24-1,"na") -> 0.081721693 | L25: =IFERROR(L24/G24-1,"na") -> 0.073716181 | M25: =IFERROR(M24/H24-1,"na") -> -0.18601172 | N25: =IFERROR(N24/I24-1,"na") -> 0.16593291 | O25: =IFERROR(O24/J24-1,"na") -> 0.27286166 | ... AU25: =IFERROR(AU24/AP24-1,"na") -> 0.069845626
A26: EBITDA margin | B26: % | C26: =IFERROR(C24/C9,"na") -> 0.23388864 | D26: =IFERROR(D24/D9,"na") -> 0.22831538 | E26: =IFERROR(E24/E9,"na") -> 0.22049467 | F26: =IFERROR(F24/F9,"na") -> 0.19210219 | G26: =IFERROR(G24/G9,"na") -> 0.21952155 | H26: =IFERROR(H24/H9,"na") -> 0.25126643 | I26: =IFERROR(I24/I9,"na") -> 0.22751256 | J26: =IFERROR(J24/J9,"na") -> 0.21799378 | ... AU26: =IFERROR(AU24/AU9,"na") -> 0.19933409
A27: Depreciation & Amortization | B27: INR Mn | C27: -321.4 | D27: -328.9 | E27: -330.1 | F27: -350.9 | G27: =C27+D27+E27+F27 -> -1331.3 | H27: -257.5 | I27: -302.9 | J27: -295.1 | K27: -295.9 | L27: =H27+I27+J27+K27 -> -1151.4 | M27: -312.6 | N27: -296.1 | O27: -292.4 | P27: -297.7 | Q27: =M27+N27+O27+P27 -> -1198.8 | R27: -301.1 | S27: -315.8 | T27: -320.9 | U27: =IFERROR((S82+S91)*U28*0.25,"na") -> -324.08872 | V27: =R27+S27+T27+U27 -> -1261.8887 | W27: =IFERROR((V82+V91)*W28*0.25,"na") -> -323.8546 | X27: =IFERROR((V82+V91)*X28*0.25,"na") -> -326.09379 | Y27: =IFERROR((V82+V91)*Y28*0.25,"na") -> -325.04936 | Z27: =IFERROR((V82+V91)*Z28*0.25,"na") -> -325.43241 | AA27: =W27+X27+Y27+Z27 -> -1300.4302 | AB27: =IFERROR((AA82+AA91)*AB28*0.25,"na") -> -342.95717 | AC27: =IFERROR((AA82+AA91)*AC28*0.25,"na") -> -343.2876 | AD27: =IFERROR((AA82+AA91)*AD28*0.25,"na") -> -343.11011 | AE27: =IFERROR((AA82+AA91)*AE28*0.25,"na") -> -343.16369 | AF27: =AB27+AC27+AD27+AE27 -> -1372.5186 | AG27: =IFERROR((AF82+AF91)*AG28*0.25,"na") -> -359.37814 | AH27: =IFERROR((AF82+AF91)*AH28*0.25,"na") -> -359.4233 | AI27: =IFERROR((AF82+AF91)*AI28*0.25,"na") -> -359.39323 | AJ27: =IFERROR((AF82+AF91)*AJ28*0.25,"na") -> -359.40212 | AK27: =AG27+AH27+AI27+AJ27 -> -1437.5968 | AL27: =IFERROR((AK82+AK91)*AL28*0.25,"na") -> -374.19502 | AM27: =IFERROR((AK82+AK91)*AM28*0.25,"na") -> -374.2005 | AN27: =IFERROR((AK82+AK91)*AN28*0.25,"na") -> -374.1956 | AO27: =IFERROR((AK82+AK91)*AO28*0.25,"na") -> -374.19729 | AP27: =AL27+AM27+AN27+AO27 -> -1496.7884 | AQ27: =IFERROR((AP82+AP91)*AQ28*0.25,"na") -> -389.90453 | AR27: =IFERROR((AP82+AP91)*AR28*0.25,"na") -> -389.90507 | AS27: =IFERROR((AP82+AP91)*AS28*0.25,"na") -> -389.90432 | AT27: =IFERROR((AP82+AP91)*AT28*0.25,"na") -> -389.90466 | AU27: =AQ27+AR27+AS27+AT27 -> -1559.6186
A28: as a % of fixed and intangible assets | B28: % | C28: na | D28: na | E28: =IFERROR(E27*4/(D82+D91),"na") -> -0.089292235 | F28: =IFERROR(F27*4/(D82+D91),"na") -> -0.094918647 | G28: na | H28: =IFERROR(H27*4/(F82+F91),"na") -> -0.068325948 | I28: =IFERROR(I27*4/(F82+F91),"na") -> -0.080372542 | J28: =IFERROR(J27*4/(I82+I91),"na") -> -0.084914143 | K28: =IFERROR(K27*4/(I82+I91),"na") -> -0.085144341 | L28: =IFERROR(L27/(G82+G91),"na") -> -0.076379123 | M28: =IFERROR(M27*4/(K82+K91),"na") -> -0.096995648 | N28: =IFERROR(N27*4/(K82+K91),"na") -> -0.091875916 | O28: =IFERROR(O27*4/(N82+N91),"na") -> -0.091249532 | P28: =IFERROR(P27*4/(N82+N91),"na") -> -0.092903508 | Q28: =IFERROR(Q27/(L82+L91),"na") -> -0.092992949 | R28: =IFERROR(R27*4/(P82+P91),"na") -> -0.086491921 | S28: =IFERROR(S27*4/(P82+P91),"na") -> -0.090714542 | T28: =IFERROR(T27*4/(S82+S91),"na") -> -0.088859352 | U28: =AVERAGE(P28,R28,S28,T28) -> -0.089742331 | V28: =IFERROR(V27/(Q82+Q91),"na") -> -0.090620375 | W28: =AVERAGE(R28,T28,U28,S28) -> -0.088952037 | X28: =AVERAGE(S28,U28,W28,T28) -> -0.089567065 | Y28: =AVERAGE(T28,W28,X28,U28) -> -0.089280196 | Z28: =AVERAGE(U28,X28,Y28,W28) -> -0.089385407 | AA28: =IFERROR(AA27/(V82+V91),"na") -> -0.089296176 | AB28: =AVERAGE(W28,Y28,Z28,X28) -> -0.089296176 | AC28: =AVERAGE(X28,Z28,AB28,Y28) -> -0.089382211 | AD28: =AVERAGE(Y28,AB28,AC28,Z28) -> -0.089335998 | AE28: =AVERAGE(Z28,AC28,AD28,AB28) -> -0.089349948 | AF28: =IFERROR(AF27/(AA82+AA91),"na") -> -0.089341083 | AG28: =AVERAGE(AB28,AD28,AE28,AC28) -> -0.089341083 | AH28: =AVERAGE(AC28,AE28,AG28,AD28) -> -0.08935231 | AI28: =AVERAGE(AD28,AG28,AH28,AE28) -> -0.089344835 | AJ28: =AVERAGE(AE28,AH28,AI28,AG28) -> -0.089347044 | AK28: =IFERROR(AK27/(AF82+AF91),"na") -> -0.089346318 | AL28: =AVERAGE(AG28,AI28,AJ28,AH28) -> -0.089346318 | AM28: =AVERAGE(AH28,AJ28,AL28,AI28) -> -0.089347627 | AN28: =AVERAGE(AI28,AL28,AM28,AJ28) -> -0.089346456 | AO28: =AVERAGE(AJ28,AM28,AN28,AL28) -> -0.089346861 | AP28: =IFERROR(AP27/(AK82+AK91),"na") -> -0.089346816 | AQ28: =AVERAGE(AL28,AN28,AO28,AM28) -> -0.089346816 | AR28: =AVERAGE(AM28,AO28,AQ28,AN28) -> -0.08934694 | AS28: =AVERAGE(AN28,AQ28,AR28,AO28) -> -0.089346768 | AT28: =AVERAGE(AO28,AR28,AS28,AQ28) -> -0.089346846 | AU28: =IFERROR(AU27/(AP82+AP91),"na") -> -0.089346842
A29: EBIT | B29: INR Mn | C29: =C24+C27 -> 3115.5 | D29: =D24+D27 -> 2685 | E29: =E24+E27 -> 2622.5 | F29: =F24+F27 -> 2032.8 | G29: =G24+G27 -> 10455.8 | H29: =H24+H27 -> 3685.8 | I29: =I24+I27 -> 2922.5 | J29: =J24+J27 -> 2613.7 | ... AU29: =AU24+AU27 -> 19020.737
A30: EBIT margin | B30: % | C30: =IFERROR(C29/C9,"na") -> 0.21201666 | D30: =IFERROR(D29/D9,"na") -> 0.20339985 | E30: =IFERROR(E29/E9,"na") -> 0.19584341 | F30: =IFERROR(F29/F9,"na") -> 0.16382319 | G30: =IFERROR(G29/G9,"na") -> 0.19472758 | H30: =IFERROR(H29/H9,"na") -> 0.23485857 | I30: =IFERROR(I29/I9,"na") -> 0.20614666 | J30: =IFERROR(J29/J9,"na") -> 0.19587814 | ... AU30: =IFERROR(AU29/AU9,"na") -> 0.18422817
A31: Finance expense | B31: INR Mn | C31: -39 | D31: -30.7 | E31: -31.3 | F31: -31.7 | G31: =C31+D31+E31+F31 -> -132.7 | H31: -35.3 | I31: -26.2 | J31: -29.7 | K31: -48.1 | L31: =H31+I31+J31+K31 -> -139.3 | M31: -37.3 | N31: -38.7 | O31: -41.1 | P31: -38.3 | Q31: =M31+N31+O31+P31 -> -155.4 | R31: -72.7 | S31: -60.2 | T31: -62.1 | U31: =IFERROR((S100+S113)*U32*0.25,"na") -> -55.486478 | V31: =R31+S31+T31+U31 -> -250.48648 | W31: =IFERROR((V100+V113)*W32*0.25,"na") -> -67.048638 | X31: =IFERROR((V100+V113)*X32*0.25,"na") -> -65.635798 | Y31: =IFERROR((V100+V113)*Y32*0.25,"na") -> -66.994747 | Z31: =IFERROR((V100+V113)*Z32*0.25,"na") -> -65.880429 | AA31: =W31+X31+Y31+Z31 -> -265.55961 | AB31: =IFERROR((AA100+AA113)*AB32*0.25,"na") -> -66.389903 | AC31: =IFERROR((AA100+AA113)*AC32*0.25,"na") -> -66.225219 | AD31: =IFERROR((AA100+AA113)*AD32*0.25,"na") -> -66.372575 | AE31: =IFERROR((AA100+AA113)*AE32*0.25,"na") -> -66.217031 | AF31: =AB31+AC31+AD31+AE31 -> -265.20473 | AG31: =IFERROR((AF100+AF113)*AG32*0.25,"na") -> -66.301182 | AH31: =IFERROR((AF100+AF113)*AH32*0.25,"na") -> -66.279002 | AI31: =IFERROR((AF100+AF113)*AI32*0.25,"na") -> -66.292447 | AJ31: =IFERROR((AF100+AF113)*AJ32*0.25,"na") -> -66.272416 | AK31: =AG31+AH31+AI31+AJ31 -> -265.14505 | AL31: =IFERROR((AK100+AK113)*AL32*0.25,"na") -> -66.286262 | AM31: =IFERROR((AK100+AK113)*AM32*0.25,"na") -> -66.282532 | AN31: =IFERROR((AK100+AK113)*AN32*0.25,"na") -> -66.283414 | AO31: =IFERROR((AK100+AK113)*AO32*0.25,"na") -> -66.281156 | AP31: =AL31+AM31+AN31+AO31 -> -265.13336 | AQ31: =IFERROR((AP100+AP113)*AQ32*0.25,"na") -> -66.283341 | AR31: =IFERROR((AP100+AP113)*AR32*0.25,"na") -> -66.282611 | AS31: =IFERROR((AP100+AP113)*AS32*0.25,"na") -> -66.28263 | AT31: =IFERROR((AP100+AP113)*AT32*0.25,"na") -> -66.282434 | AU31: =AQ31+AR31+AS31+AT31 -> -265.13102
A32: as a % of total debt | B32: % | C32: na | D32: na | E32: =IFERROR(E31*4/(D100+D113),"na") -> -0.22281545 | F32: =IFERROR(F31*4/(D100+D113),"na") -> -0.22566293 | G32: na | H32: =IFERROR(H31*4/(F100+F113),"na") -> -0.16753678 | I32: =IFERROR(I31*4/(F100+F113),"na") -> -0.12434741 | J32: =IFERROR(J31*4/(I100+I113),"na") -> -0.11870504 | K32: =IFERROR(K31*4/(I100+I113),"na") -> -0.1922462 | L32: =IFERROR(L31/(G100+G113),"na") -> -0.16528239 | M32: =IFERROR(M31*4/(K100+K113),"na") -> -0.15300995 | N32: =IFERROR(N31*4/(K100+K113),"na") -> -0.15875295 | O32: =IFERROR(O31*4/(N100+N113),"na") -> -0.17869565 | P32: =IFERROR(P31*4/(N100+N113),"na") -> -0.16652174 | Q32: =IFERROR(Q31/(L100+L113),"na") -> -0.15936827 | R32: =IFERROR(R31*4/(P100+P113),"na") -> -0.2372909 | S32: =IFERROR(S31*4/(P100+P113),"na") -> -0.19649123 | T32: =IFERROR(T31*4/(S100+S113),"na") -> -0.23321754 | U32: =AVERAGE(P32,R32,S32,T32) -> -0.20838035 | V32: =IFERROR(V31/(Q100+Q113),"na") -> -0.20439533 | W32: =AVERAGE(R32,T32,U32,S32) -> -0.218845 | X32: =AVERAGE(S32,U32,W32,T32) -> -0.21423353 | Y32: =AVERAGE(T32,W32,X32,U32) -> -0.21866911 | Z32: =AVERAGE(U32,X32,Y32,W32) -> -0.215032 | AA32: =IFERROR(AA31/(V100+V113),"na") -> -0.21669491 | AB32: =AVERAGE(W32,Y32,Z32,X32) -> -0.21669491 | AC32: =AVERAGE(X32,Z32,AB32,Y32) -> -0.21615739 | AD32: =AVERAGE(Y32,AB32,AC32,Z32) -> -0.21663835 | AE32: =AVERAGE(Z32,AC32,AD32,AB32) -> -0.21613066 | AF32: =IFERROR(AF31/(AA100+AA113),"na") -> -0.21640533 | AG32: =AVERAGE(AB32,AD32,AE32,AC32) -> -0.21640533 | AH32: =AVERAGE(AC32,AE32,AG32,AD32) -> -0.21633293 | AI32: =AVERAGE(AD32,AG32,AH32,AE32) -> -0.21637682 | AJ32: =AVERAGE(AE32,AH32,AI32,AG32) -> -0.21631143 | AK32: =IFERROR(AK31/(AF100+AF113),"na") -> -0.21635663 | AL32: =AVERAGE(AG32,AI32,AJ32,AH32) -> -0.21635663 | AM32: =AVERAGE(AH32,AJ32,AL32,AI32) -> -0.21634445 | AN32: =AVERAGE(AI32,AL32,AM32,AJ32) -> -0.21634733 | AO32: =AVERAGE(AJ32,AM32,AN32,AL32) -> -0.21633996 | AP32: =IFERROR(AP31/(AK100+AK113),"na") -> -0.21634709 | AQ32: =AVERAGE(AL32,AN32,AO32,AM32) -> -0.21634709 | AR32: =AVERAGE(AM32,AO32,AQ32,AN32) -> -0.21634471 | AS32: =AVERAGE(AN32,AQ32,AR32,AO32) -> -0.21634477 | AT32: =AVERAGE(AO32,AR32,AS32,AQ32) -> -0.21634414 | AU32: =IFERROR(AU31/(AP100+AP113),"na") -> -0.21634518
A33: Finance income | B33: INR Mn | C33: 104.5 | D33: 122.5 | E33: 96.7 | F33: 186.2 | G33: =C33+D33+E33+F33 -> 509.9 | H33: 240.7 | I33: 323.9 | J33: 272.3 | K33: 285.6 | L33: =H33+I33+J33+K33 -> 1122.5 | M33: 432.2 | N33: 336.7 | O33: 194.5 | P33: 520.7 | Q33: =M33+N33+O33+P33 -> 1484.1 | R33: 321.3 | S33: 276.3 | T33: 306.7 | U33: =IFERROR((S68+S86)*U34*0.25,"na") -> 352.96721 | V33: =R33+S33+T33+U33 -> 1257.2672 | W33: =IFERROR((V68+V86)*W34*0.25,"na") -> 301.26308 | X33: =IFERROR((V68+V86)*X34*0.25,"na") -> 296.25385 | Y33: =IFERROR((V68+V86)*Y34*0.25,"na") -> 301.24231 | Z33: =IFERROR((V68+V86)*Z34*0.25,"na") -> 305.94698 | AA33: =W33+X33+Y33+Z33 -> 1204.7062 | AB33: =IFERROR((AA68+AA86)*AB34*0.25,"na") -> 301.17655 | AC33: =IFERROR((AA68+AA86)*AC34*0.25,"na") -> 301.15492 | AD33: =IFERROR((AA68+AA86)*AD34*0.25,"na") -> 302.38019 | AE33: =IFERROR((AA68+AA86)*AE34*0.25,"na") -> 302.66466 | AF33: =AB33+AC33+AD33+AE33 -> 1207.3763 | AG33: =IFERROR((AF68+AF86)*AG34*0.25,"na") -> 301.84408 | AH33: =IFERROR((AF68+AF86)*AH34*0.25,"na") -> 302.01096 | AI33: =IFERROR((AF68+AF86)*AI34*0.25,"na") -> 302.22497 | AJ33: =IFERROR((AF68+AF86)*AJ34*0.25,"na") -> 302.18617 | AK33: =AG33+AH33+AI33+AJ33 -> 1208.2662 | AL33: =IFERROR((AK68+AK86)*AL34*0.25,"na") -> 302.06655 | AM33: =IFERROR((AK68+AK86)*AM34*0.25,"na") -> 302.12216 | AN33: =IFERROR((AK68+AK86)*AN34*0.25,"na") -> 302.14996 | AO33: =IFERROR((AK68+AK86)*AO34*0.25,"na") -> 302.13121 | AP33: =AL33+AM33+AN33+AO33 -> 1208.4699 | AQ33: =IFERROR((AP68+AP86)*AQ34*0.25,"na") -> 302.11747 | AR33: =IFERROR((AP68+AP86)*AR34*0.25,"na") -> 302.1302 | AS33: =IFERROR((AP68+AP86)*AS34*0.25,"na") -> 302.13221 | AT33: =IFERROR((AP68+AP86)*AT34*0.25,"na") -> 302.12777 | AU33: =AQ33+AR33+AS33+AT33 -> 1208.5077
A34: as a % of investments | B34: % | C34: na | D34: na | E34: =IFERROR(E33*4/(D68+D86),"na") -> 0.061758554 | F34: =IFERROR(F33*4/(D68+D86),"na") -> 0.11891875 | G34: na | H34: =IFERROR(H33*4/(F68+F86),"na") -> 0.12892513 | I34: =IFERROR(I33*4/(F68+F86),"na") -> 0.1734892 | J34: =IFERROR(J33*4/(I68+I86),"na") -> 0.094365941 | K34: =IFERROR(K33*4/(I68+I86),"na") -> 0.098975074 | L34: =IFERROR(L33/(G68+G86),"na") -> 0.15030999 | M34: =IFERROR(M33*4/(K68+K86),"na") -> 0.11635248 | N34: =IFERROR(N33*4/(K68+K86),"na") -> 0.09064294 | O34: =IFERROR(O33*4/(N68+N86),"na") -> 0.049593942 | P34: =IFERROR(P33*4/(N68+N86),"na") -> 0.13276897 | Q34: =IFERROR(Q33/(L68+L86),"na") -> 0.099883567 | R34: =IFERROR(R33*4/(P68+P86),"na") -> 0.10154627 | S34: =IFERROR(S33*4/(P68+P86),"na") -> 0.087324099 | T34: =IFERROR(T33*4/(S68+S86),"na") -> 0.089259469 | U34: =AVERAGE(P34,R34,S34,T34) -> 0.1027247 | V34: =IFERROR(V33/(Q68+Q86),"na") -> 0.099339239 | W34: =AVERAGE(R34,T34,U34,S34) -> 0.095213634 | X34: =AVERAGE(S34,U34,W34,T34) -> 0.093630476 | Y34: =AVERAGE(T34,W34,X34,U34) -> 0.09520707 | Z34: =AVERAGE(U34,X34,Y34,W34) -> 0.096693971 | AA34: =IFERROR(AA33/(V68+V86),"na") -> 0.095186288 | AB34: =AVERAGE(W34,Y34,Z34,X34) -> 0.095186288 | AC34: =AVERAGE(X34,Z34,AB34,Y34) -> 0.095179451 | AD34: =AVERAGE(Y34,AB34,AC34,Z34) -> 0.095566695 | AE34: =AVERAGE(Z34,AC34,AD34,AB34) -> 0.095656601 | AF34: =IFERROR(AF33/(AA68+AA86),"na") -> 0.095397259 | AG34: =AVERAGE(AB34,AD34,AE34,AC34) -> 0.095397259 | AH34: =AVERAGE(AC34,AE34,AG34,AD34) -> 0.095450002 | AI34: =AVERAGE(AD34,AG34,AH34,AE34) -> 0.095517639 | AJ34: =AVERAGE(AE34,AH34,AI34,AG34) -> 0.095505375 | AK34: =IFERROR(AK33/(AF68+AF86),"na") -> 0.095467569 | AL34: =AVERAGE(AG34,AI34,AJ34,AH34) -> 0.095467569 | AM34: =AVERAGE(AH34,AJ34,AL34,AI34) -> 0.095485146 | AN34: =AVERAGE(AI34,AL34,AM34,AJ34) -> 0.095493932 | AO34: =AVERAGE(AJ34,AM34,AN34,AL34) -> 0.095488006 | AP34: =IFERROR(AP33/(AK68+AK86),"na") -> 0.095483663 | AQ34: =AVERAGE(AL34,AN34,AO34,AM34) -> 0.095483663 | AR34: =AVERAGE(AM34,AO34,AQ34,AN34) -> 0.095487687 | AS34: =AVERAGE(AN34,AQ34,AR34,AO34) -> 0.095488322 | AT34: =AVERAGE(AO34,AR34,AS34,AQ34) -> 0.095486919 | AU34: =IFERROR(AU33/(AP68+AP86),"na") -> 0.095486648
A35: Share of profit of JV and Associate | B35: INR Mn | C35: =C36+C37 -> 3.6 | D35: =D36+D37 -> 4.6 | E35: =E36+E37 -> 7.6 | F35: =F36+F37 -> 13.5 | G35: =G36+G37 -> 29.3 | H35: =H36+H37 -> 8.6 | I35: =I36+I37 -> 15.2 | J35: =J36+J37 -> 5.7 | ... AU35: =AU36+AU37 -> 40
A36: Share of profit of associate | B36: INR Mn | C36: 3.6 | D36: 4.6 | E36: 7.6 | F36: 13.5 | G36: =C36+D36+E36+F36 -> 29.3 | H36: 8.6 | I36: 15.2 | J36: 5.7 | K36: 14.1 | L36: =H36+I36+J36+K36 -> 43.6 | M36: 4.3 | N36: 10.8 | O36: 18.5 | P36: 13.9 | Q36: =M36+N36+O36+P36 -> 47.5 | R36: 4.6 | S36: -1.1 | T36: 17.8 | U36: 8 | V36: =R36+S36+T36+U36 -> 29.3 | W36: 8 | X36: =W36 -> 8 | Y36: =X36 -> 8 | Z36: =Y36 -> 8 | AA36: =W36+X36+Y36+Z36 -> 32 | AB36: =Z36 -> 8 | AC36: =AB36 -> 8 | AD36: =AC36 -> 8 | AE36: =AD36 -> 8 | AF36: =AB36+AC36+AD36+AE36 -> 32 | AG36: =AE36 -> 8 | AH36: =AG36 -> 8 | AI36: =AH36 -> 8 | AJ36: =AI36 -> 8 | AK36: =AG36+AH36+AI36+AJ36 -> 32 | AL36: =AJ36 -> 8 | AM36: =AL36 -> 8 | AN36: =AM36 -> 8 | AO36: =AN36 -> 8 | AP36: =AL36+AM36+AN36+AO36 -> 32 | AQ36: =AO36 -> 8 | AR36: =AQ36 -> 8 | AS36: =AR36 -> 8 | AT36: =AS36 -> 8 | AU36: =AQ36+AR36+AS36+AT36 -> 32
A37: Share of profit of JV | B37: INR Mn | C37: 0 | D37: 0 | E37: 0 | F37: 0 | G37: =C37+D37+E37+F37 -> 0 | H37: 0 | I37: 0 | J37: 0 | K37: 9.4 | L37: =H37+I37+J37+K37 -> 9.4 | M37: 1.2 | N37: 0.4 | O37: 2.5 | P37: -5.7 | Q37: =M37+N37+O37+P37 -> -1.6 | R37: -0.4 | S37: -5.4 | T37: -3.1 | U37: 2 | V37: =R37+S37+T37+U37 -> -6.9 | W37: 2 | X37: =W37 -> 2 | Y37: =X37 -> 2 | Z37: =Y37 -> 2 | AA37: =W37+X37+Y37+Z37 -> 8 | AB37: =Z37 -> 2 | AC37: =AB37 -> 2 | AD37: =AC37 -> 2 | AE37: =AD37 -> 2 | AF37: =AB37+AC37+AD37+AE37 -> 8 | AG37: =AE37 -> 2 | AH37: =AG37 -> 2 | AI37: =AH37 -> 2 | AJ37: =AI37 -> 2 | AK37: =AG37+AH37+AI37+AJ37 -> 8 | AL37: =AJ37 -> 2 | AM37: =AL37 -> 2 | AN37: =AM37 -> 2 | AO37: =AN37 -> 2 | AP37: =AL37+AM37+AN37+AO37 -> 8 | AQ37: =AO37 -> 2 | AR37: =AQ37 -> 2 | AS37: =AR37 -> 2 | AT37: =AS37 -> 2 | AU37: =AQ37+AR37+AS37+AT37 -> 8
A38: Exceptional items | B38: INR Mn | C38: 5.5 | D38: -12.3 | E38: -6.7 | F38: -34.6 | G38: =C38+D38+E38+F38 -> -48.1 | H38: -4 | I38: -11.4 | J38: -42.7 | K38: 0 | L38: =H38+I38+J38+K38 -> -58.1 | M38: 0 | N38: 0 | O38: 0 | P38: 0 | Q38: =M38+N38+O38+P38 -> 0 | R38: 0 | S38: 0 | T38: 0 | U38: 0 | V38: =R38+S38+T38+U38 -> 0 | W38: 0 | X38: 0 | Y38: 0 | Z38: 0 | AA38: =W38+X38+Y38+Z38 -> 0 | AB38: 0 | AC38: 0 | AD38: 0 | AE38: 0 | AF38: =AB38+AC38+AD38+AE38 -> 0 | AG38: 0 | AH38: 0 | AI38: 0 | AJ38: 0 | AK38: =AG38+AH38+AI38+AJ38 -> 0 | AL38: 0 | AM38: 0 | AN38: 0 | AO38: 0 | AP38: =AL38+AM38+AN38+AO38 -> 0 | AQ38: 0 | AR38: 0 | AS38: 0 | AT38: 0 | AU38: =AQ38+AR38+AS38+AT38 -> 0
A39: PBT | B39: INR Mn | C39: =C29+C31+C33+C35+C38 -> 3190.1 | D39: =D29+D31+D33+D35+D38 -> 2769.1 | E39: =E29+E31+E33+E35+E38 -> 2688.8 | F39: =F29+F31+F33+F35+F38 -> 2166.2 | G39: =G29+G31+G33+G35+G38 -> 10814.2 | H39: =H29+H31+H33+H35+H38 -> 3895.8 | I39: =I29+I31+I33+I35+I38 -> 3224 | J39: =J29+J31+J33+J35+J38 -> 2819.3 | ... AU39: =AU29+AU31+AU33+AU35+AU38 -> 20004.114
A40: Tax | B40: INR Mn | C40: =C41+C43 -> -925.9 | D40: =D41+D43 -> -835.7 | E40: =E41+E43 -> -822.1 | F40: =F41+F43 -> -637.4 | G40: =G41+G43 -> -3221.1 | H40: =H41+H43 -> -1174.3 | I40: =I41+I43 -> -911.7 | J40: =J41+J43 -> -793.2 | ... AU40: =AU41+AU43 -> -6181.2712
A41: Current tax | B41: INR Mn | C41: -925.9 | D41: -835.7 | E41: -822.1 | F41: -637.4 | G41: =C41+D41+E41+F41 -> -3221.1 | H41: -1174.3 | I41: -911.7 | J41: -793.2 | K41: -951.2 | L41: =H41+I41+J41+K41 -> -3830.4 | M41: -980.3 | N41: -1211.4 | O41: -1144.6 | P41: -404.5 | Q41: =M41+N41+O41+P41 -> -3740.8 | R41: -1342.8 | S41: -1131.8 | T41: -1183.8 | U41: =-IFERROR(U39*U42,"na") -> -1042.4615 | V41: =R41+S41+T41+U41 -> -4700.8615 | W41: =-IFERROR(W39*W42,"na") -> -1170.7209 | X41: =-IFERROR(X39*X42,"na") -> -1101.4873 | Y41: =-IFERROR(Y39*Y42,"na") -> -1151.9671 | Z41: =-IFERROR(Z39*Z42,"na") -> -1111.3597 | AA41: =W41+X41+Y41+Z41 -> -4535.5349 | AB41: =-IFERROR(AB39*AB42,"na") -> -1254.2423 | AC41: =-IFERROR(AC39*AC42,"na") -> -1199.3276 | AD41: =-IFERROR(AD39*AD42,"na") -> -1262.6358 | AE41: =-IFERROR(AE39*AE42,"na") -> -1212.6126 | AF41: =AB41+AC41+AD41+AE41 -> -4928.8183 | AG41: =-IFERROR(AG39*AG42,"na") -> -1337.147 | AH41: =-IFERROR(AH39*AH42,"na") -> -1279.7903 | AI41: =-IFERROR(AI39*AI42,"na") -> -1347.7771 | AJ41: =-IFERROR(AJ39*AJ42,"na") -> -1294.1839 | AK41: =AG41+AH41+AI41+AJ41 -> -5258.8983 | AL41: =-IFERROR(AL39*AL42,"na") -> -1428.1117 | AM41: =-IFERROR(AM39*AM42,"na") -> -1366.8193 | AN41: =-IFERROR(AN39*AN42,"na") -> -1439.5128 | AO41: =-IFERROR(AO39*AO42,"na") -> -1382.5465 | AP41: =AL41+AM41+AN41+AO41 -> -5616.9903 | AQ41: =-IFERROR(AQ39*AQ42,"na") -> -1525.7466 | AR41: =-IFERROR(AR39*AR42,"na") -> -1460.1714 | AS41: =-IFERROR(AS39*AS42,"na") -> -1537.9285 | AT41: =-IFERROR(AT39*AT42,"na") -> -1477.3876 | AU41: =AQ41+AR41+AS41+AT41 -> -6001.2342
A42: corporate tax | B42: % | C42: =-IFERROR(C41/C39,"na") -> 0.29024169 | D42: =-IFERROR(D41/D39,"na") -> 0.30179481 | E42: =-IFERROR(E41/E39,"na") -> 0.30574978 | F42: =-IFERROR(F41/F39,"na") -> 0.29424799 | G42: =-IFERROR(G41/G39,"na") -> 0.29785837 | H42: =-IFERROR(H41/H39,"na") -> 0.30142718 | I42: =-IFERROR(I41/I39,"na") -> 0.28278536 | J42: =-IFERROR(J41/J39,"na") -> 0.28134643 | ... T42: =-IFERROR(T41/T39,"na") -> 0.35808706 | U42: 0.3 | V42: =-IFERROR(V41/V39,"na") -> 0.33360094 | W42: 0.3 | X42: =W42 -> 0.3 | Y42: =X42 -> 0.3 | Z42: =Y42 -> 0.3 | AA42: =-IFERROR(AA41/AA39,"na") -> 0.3 | AB42: =Z42 -> 0.3 | AC42: =AB42 -> 0.3 | AD42: =AC42 -> 0.3 | AE42: =AD42 -> 0.3 | AF42: =-IFERROR(AF41/AF39,"na") -> 0.3 | AG42: =AE42 -> 0.3 | AH42: =AG42 -> 0.3 | AI42: =AH42 -> 0.3 | AJ42: =AI42 -> 0.3 | AK42: =-IFERROR(AK41/AK39,"na") -> 0.3 | AL42: =AJ42 -> 0.3 | AM42: =AL42 -> 0.3 | AN42: =AM42 -> 0.3 | AO42: =AN42 -> 0.3 | AP42: =-IFERROR(AP41/AP39,"na") -> 0.3 | AQ42: =AO42 -> 0.3 | AR42: =AQ42 -> 0.3 | AS42: =AR42 -> 0.3 | AT42: =AS42 -> 0.3 | AU42: =-IFERROR(AU41/AU39,"na") -> 0.3
A43: Deferred tax | B43: INR Mn | C43: 0 | D43: 0 | E43: 0 | F43: 0 | G43: =C43+D43+E43+F43 -> 0 | H43: 0 | I43: 0 | J43: 0 | K43: -20.1 | L43: =H43+I43+J43+K43 -> -20.1 | M43: -52.2 | N43: -33.1 | O43: -48.5 | P43: -52.5 | Q43: =M43+N43+O43+P43 -> -186.3 | R43: -17.7 | S43: -98.6 | T43: 73.5 | U43: =IFERROR(U41*U44,"na") -> -31.273845 | V43: =R43+S43+T43+U43 -> -74.073845 | W43: =IFERROR(W41*W44,"na") -> -35.121627 | X43: =IFERROR(X41*X44,"na") -> -33.044618 | Y43: =IFERROR(Y41*Y44,"na") -> -34.559013 | Z43: =IFERROR(Z41*Z44,"na") -> -33.34079 | AA43: =W43+X43+Y43+Z43 -> -136.06605 | AB43: =IFERROR(AB41*AB44,"na") -> -37.62727 | AC43: =IFERROR(AC41*AC44,"na") -> -35.979827 | AD43: =IFERROR(AD41*AD44,"na") -> -37.879073 | AE43: =IFERROR(AE41*AE44,"na") -> -36.378379 | AF43: =AB43+AC43+AD43+AE43 -> -147.86455 | AG43: =IFERROR(AG41*AG44,"na") -> -40.11441 | AH43: =IFERROR(AH41*AH44,"na") -> -38.393708 | AI43: =IFERROR(AI41*AI44,"na") -> -40.433313 | AJ43: =IFERROR(AJ41*AJ44,"na") -> -38.825518 | AK43: =AG43+AH43+AI43+AJ43 -> -157.76695 | AL43: =IFERROR(AL41*AL44,"na") -> -42.843351 | AM43: =IFERROR(AM41*AM44,"na") -> -41.00458 | AN43: =IFERROR(AN41*AN44,"na") -> -43.185384 | AO43: =IFERROR(AO41*AO44,"na") -> -41.476394 | AP43: =AL43+AM43+AN43+AO43 -> -168.50971 | AQ43: =IFERROR(AQ41*AQ44,"na") -> -45.772398 | AR43: =IFERROR(AR41*AR44,"na") -> -43.805142 | AS43: =IFERROR(AS41*AS44,"na") -> -46.137856 | AT43: =IFERROR(AT41*AT44,"na") -> -44.321629 | AU43: =AQ43+AR43+AS43+AT43 -> -180.03703
...

